Workbook
Name Линия: инфо!$C$34:$C$35
Name Мастер: инфо!$A$34:$A$37
Name Продукт: инфо!$A$15:$A$29

Sheet рапорт
A1: дата | B1: № партии | C1: линия | D1: смена | E1: мастер | F1: продукт | G1: замес | H1: Формовка, лист | I1: Формовка, тонна | J1: На склад | K1: 1-сорт | L1: брак | M1: количество сбросов наката | N1: асбест | O1: Цемент | S1: цемент | T1: асб-слив | U1: цем-слив | V1: Лапрорл | X1: Целлюлоза | Z1: Стекловолокно | AB1: Д/ШИФЕР | AD1: асбозурит | AE1: норма А | AF1: факт А | AG1: откл | AH1: норма Ц | AI1: факт Ц | AJ1: откл | AK1: норма ЦЛ | AL1: факт ЦЛ | AM1: откл | AN1: норма СВ | AO1: факт СВ | AP1: откл | AQ1: норма ФБ | AR1: факт ФБ | AS1: откл | AT1: норма АСБ | AU1: факт АСБ | AV1: откл | AX1: масса, тн
O2: 1 силос | P2: 2 силос | Q2: 3 силос | R2: 4 силос | V2: Приход | W2: Расход | X2: Приход | Y2: Расход | Z2: Приход | AA2: Расход | AB2: Приход | AC2: Расход
A3: 46069 | B3: 0001 | C3: Линия 1 | D3: день | E3: Монаев | F3: РП | G3: 9 | H3: 268 | I3: =IFERROR(H3*VLOOKUP(F3,инфо!$A$15:$C$28,3,FALSE)/1000,0) -> 4.67124 | N3: 908 | O3: 5400 | P3: 0 | Q3: 0 | R3: 0 | S3: =SUM(O3:R3) -> 5400 | T3: 0 | U3: 0 | Y3: 90 | AA3: 0 | AC3: 90 | AD3: 0 | AE3: =SUMIFS(инфо!$D$15:$D$28,инфо!$A$15:$A$28,F3) -> 2.06 | AF3: =IF(H3=0,0,N3/H3) -> 3.3880597 | AG3: =AF3-AE3 -> 1.3280597 | AH3: =SUMIFS(инфо!$E$15:$E$28,инфо!$A$15:$A$28,F3) -> 13.28 | AI3: =IF(H3=0,0,S3/H3) -> 20.149254 | AJ3: =AI3-AH3 -> 6.8692537 | AK3: =SUMIFS(инфо!$F$15:$F$28,инфо!$A$15:$A$28,F3) -> 0.205 | AL3: =IF(H3=0,0,Y3/H3) -> 0.3358209 | AM3: =AL3-AK3 -> 0.1308209 | AN3: =SUMIFS(инфо!$G$15:$G$28,инфо!$A$15:$A$28,F3) -> 0.041 | AO3: =IF(H3=0,0,AA3/H3) -> 0 | AP3: =AO3-AN3 -> -0.041 | AQ3: =SUMIFS(инфо!$H$15:$H$28,инфо!$A$15:$A$28,F3) -> 0 | AR3: =IF(H3=0,0,AC3/H3) -> 0.3358209 | AS3: =AR3-AQ3 -> 0.3358209 | AT3: =SUMIFS(инфо!$I$15:$I$28,инфо!$A$15:$A$28,F3) -> 0.103 | AU3: =IF(H3=0,0,AD3/H3) -> 0 | AV3: =AU3-AT3 -> -0.103 | AX3: =SUMIFS(инфо!$C$15:$C$28,инфо!$A$15:$A$28,F3)*H3 -> 4671.24
A4: 46069 | B4: 0002 | C4: Линия 1 | D4: ночь | E4: Дауылбай | F4: РП коричневый | G4: 27 | H4: 1265 | I4: =IFERROR(H4*VLOOKUP(F4,инфо!$A$15:$C$28,3,FALSE)/1000,0) -> 22.04895 | K4: 13 | L4: 47 | N4: 2706 | O4: 16186 | S4: =SUM(O4:R4) -> 16186 | Y4: 270 | AC4: 270 | AE4: =SUMIFS(инфо!$D$15:$D$28,инфо!$A$15:$A$28,F4) -> 2.06 | AF4: =IF(H4=0,0,N4/H4) -> 2.1391304 | AG4: =AF4-AE4 -> 0.079130435 | AH4: =SUMIFS(инфо!$E$15:$E$28,инфо!$A$15:$A$28,F4) -> 13.28 | AI4: =IF(H4=0,0,S4/H4) -> 12.795257 | AJ4: =AI4-AH4 -> -0.48474308 | AK4: =SUMIFS(инфо!$F$15:$F$28,инфо!$A$15:$A$28,F4) -> 0.205 | AL4: =IF(H4=0,0,Y4/H4) -> 0.21343874 | AM4: =AL4-AK4 -> 0.0084387352 | AN4: =SUMIFS(инфо!$G$15:$G$28,инфо!$A$15:$A$28,F4) -> 0.041 | AO4: =IF(H4=0,0,AA4/H4) -> 0 | AP4: =AO4-AN4 -> -0.041 | AQ4: =SUMIFS(инфо!$H$15:$H$28,инфо!$A$15:$A$28,F4) -> 0 | AR4: =IF(H4=0,0,AC4/H4) -> 0.21343874 | AS4: =AR4-AQ4 -> 0.21343874 | AT4: =SUMIFS(инфо!$I$15:$I$28,инфо!$A$15:$A$28,F4) -> 0.103 | AU4: =IF(H4=0,0,AD4/H4) -> 0 | AV4: =AU4-AT4 -> -0.103 | AX4: =SUMIFS(инфо!$C$15:$C$28,инфо!$A$15:$A$28,F4)*H4 -> 22048.95
A5: =A3+1 -> 46070 | B5: 0003 | C5: Линия 1 | D5: день | E5: Султанулы | F5: РП коричневый | G5: 20 | H5: 996 | I5: =IFERROR(H5*VLOOKUP(F5,инфо!$A$15:$C$28,3,FALSE)/1000,0) -> 17.36028 | K5: 12 | N5: 2003 | O5: 12092 | S5: =SUM(O5:R5) -> 12092 | Y5: 200 | AC5: 190 | AE5: =SUMIFS(инфо!$D$15:$D$28,инфо!$A$15:$A$28,F5) -> 2.06 | AF5: =IF(H5=0,0,N5/H5) -> 2.0110442 | AG5: =AF5-AE5 -> -0.048955823 | AH5: =SUMIFS(инфо!$E$15:$E$28,инфо!$A$15:$A$28,F5) -> 13.28 | AI5: =IF(H5=0,0,S5/H5) -> 12.140562 | AJ5: =AI5-AH5 -> -1.1394378 | AK5: =SUMIFS(инфо!$F$15:$F$28,инфо!$A$15:$A$28,F5) -> 0.205 | AL5: =IF(H5=0,0,Y5/H5) -> 0.20080321 | AM5: =AL5-AK5 -> -0.0041967871 | AN5: =SUMIFS(инфо!$G$15:$G$28,инфо!$A$15:$A$28,F5) -> 0.041 | AO5: =IF(H5=0,0,AA5/H5) -> 0 | AP5: =AO5-AN5 -> -0.041 | AQ5: =SUMIFS(инфо!$H$15:$H$28,инфо!$A$15:$A$28,F5) -> 0 | AR5: =IF(H5=0,0,AC5/H5) -> 0.19076305 | AS5: =AR5-AQ5 -> 0.19076305 | AT5: =SUMIFS(инфо!$I$15:$I$28,инфо!$A$15:$A$28,F5) -> 0.103 | AU5: =IF(H5=0,0,AD5/H5) -> 0 | AV5: =AU5-AT5 -> -0.103 | AX5: =SUMIFS(инфо!$C$15:$C$28,инфо!$A$15:$A$28,F5)*H5 -> 17360.28
A6: 46070 | B6: 0004 | C6: Линия 1 | D6: ночь | E6: Монаев | F6: РП коричневый | G6: 31 | H6: 1441 | I6: =IFERROR(H6*VLOOKUP(F6,инфо!$A$15:$C$28,3,FALSE)/1000,0) -> 25.11663 | K6: 2 | L6: 4 | N6: 3117 | O6: 18988 | S6: =SUM(O6:R6) -> 18988 | Y6: 310 | AC6: 310 | AD6: 155 | AE6: =SUMIFS(инфо!$D$15:$D$28,инфо!$A$15:$A$28,F6) -> 2.06 | AF6: =IF(H6=0,0,N6/H6) -> 2.1630812 | AG6: =AF6-AE6 -> 0.10308119 | AH6: =SUMIFS(инфо!$E$15:$E$28,инфо!$A$15:$A$28,F6) -> 13.28 | AI6: =IF(H6=0,0,S6/H6) -> 13.17696 | AJ6: =AI6-AH6 -> -0.10303956 | AK6: =SUMIFS(инфо!$F$15:$F$28,инфо!$A$15:$A$28,F6) -> 0.205 | AL6: =IF(H6=0,0,Y6/H6) -> 0.21512838 | AM6: =AL6-AK6 -> 0.010128383 | AN6: =SUMIFS(инфо!$G$15:$G$28,инфо!$A$15:$A$28,F6) -> 0.041 | AO6: =IF(H6=0,0,AA6/H6) -> 0 | AP6: =AO6-AN6 -> -0.041 | AQ6: =SUMIFS(инфо!$H$15:$H$28,инфо!$A$15:$A$28,F6) -> 0 | AR6: =IF(H6=0,0,AC6/H6) -> 0.21512838 | AS6: =AR6-AQ6 -> 0.21512838 | AT6: =SUMIFS(инфо!$I$15:$I$28,инфо!$A$15:$A$28,F6) -> 0.103 | AU6: =IF(H6=0,0,AD6/H6) -> 0.10756419 | AV6: =AU6-AT6 -> 0.0045641915 | AX6: =SUMIFS(инфо!$C$15:$C$28,инфо!$A$15:$A$28,F6)*H6 -> 25116.63
A7: 46071 | B7: 0005 | C7: Линия 1 | D7: день | E7: Султанулы | F7: РП коричневый | G7: 13 | H7: 612 | I7: =IFERROR(H7*VLOOKUP(F7,инфо!$A$15:$C$28,3,FALSE)/1000,0) -> 10.66716 | K7: 4 | L7: 6 | N7: 1328 | O7: 1223 | P7: 6617 | S7: =SUM(O7:R7) -> 7840 | Y7: 130 | AC7: 110 | AE7: =SUMIFS(инфо!$D$15:$D$28,инфо!$A$15:$A$28,F7) -> 2.06 | AF7: =IF(H7=0,0,N7/H7) -> 2.1699346 | AG7: =AF7-AE7 -> 0.10993464 | AH7: =SUMIFS(инфо!$E$15:$E$28,инфо!$A$15:$A$28,F7) -> 13.28 | AI7: =IF(H7=0,0,S7/H7) -> 12.810458 | AJ7: =AI7-AH7 -> -0.46954248 | AK7: =SUMIFS(инфо!$F$15:$F$28,инфо!$A$15:$A$28,F7) -> 0.205 | AL7: =IF(H7=0,0,Y7/H7) -> 0.2124183 | AM7: =AL7-AK7 -> 0.0074183007 | AN7: =SUMIFS(инфо!$G$15:$G$28,инфо!$A$15:$A$28,F7) -> 0.041 | AO7: =IF(H7=0,0,AA7/H7) -> 0 | AP7: =AO7-AN7 -> -0.041 | AQ7: =SUMIFS(инфо!$H$15:$H$28,инфо!$A$15:$A$28,F7) -> 0 | AR7: =IF(H7=0,0,AC7/H7) -> 0.17973856 | AS7: =AR7-AQ7 -> 0.17973856 | AT7: =SUMIFS(инфо!$I$15:$I$28,инфо!$A$15:$A$28,F7) -> 0.103 | AU7: =IF(H7=0,0,AD7/H7) -> 0 | AV7: =AU7-AT7 -> -0.103 | AX7: =SUMIFS(инфо!$C$15:$C$28,инфо!$A$15:$A$28,F7)*H7 -> 10667.16
A8: =A6+1 -> 46071 | B8: 0006 | C8: Линия 1 | D8: ночь | E8: Монаев | F8: РП коричневый | G8: 31 | H8: 1491 | I8: =IFERROR(H8*VLOOKUP(F8,инфо!$A$15:$C$28,3,FALSE)/1000,0) -> 25.98813 | K8: 17 | L8: 8 | N8: 3117 | O8: 12200 | P8: 6719 | S8: =SUM(O8:R8) -> 18919 | Y8: 310 | AC8: 310 | AE8: =SUMIFS(инфо!$D$15:$D$28,инфо!$A$15:$A$28,F8) -> 2.06 | AF8: =IF(H8=0,0,N8/H8) -> 2.0905433 | AG8: =AF8-AE8 -> 0.03054326 | AH8: =SUMIFS(инфо!$E$15:$E$28,инфо!$A$15:$A$28,F8) -> 13.28 | AI8: =IF(H8=0,0,S8/H8) -> 12.688799 | AJ8: =AI8-AH8 -> -0.59120054 | AK8: =SUMIFS(инфо!$F$15:$F$28,инфо!$A$15:$A$28,F8) -> 0.205 | AL8: =IF(H8=0,0,Y8/H8) -> 0.20791415 | AM8: =AL8-AK8 -> 0.0029141516 | AN8: =SUMIFS(инфо!$G$15:$G$28,инфо!$A$15:$A$28,F8) -> 0.041 | AO8: =IF(H8=0,0,AA8/H8) -> 0 | AP8: =AO8-AN8 -> -0.041 | AQ8: =SUMIFS(инфо!$H$15:$H$28,инфо!$A$15:$A$28,F8) -> 0 | AR8: =IF(H8=0,0,AC8/H8) -> 0.20791415 | AS8: =AR8-AQ8 -> 0.20791415 | AT8: =SUMIFS(инфо!$I$15:$I$28,инфо!$A$15:$A$28,F8) -> 0.103 | AU8: =IF(H8=0,0,AD8/H8) -> 0 | AV8: =AU8-AT8 -> -0.103 | AX8: =SUMIFS(инфо!$C$15:$C$28,инфо!$A$15:$A$28,F8)*H8 -> 25988.13
A9: =A7+1 -> 46072 | B9: 0007 | C9: Линия 1 | D9: день | E9: Дауылбай | F9: РП коричневый | G9: 32 | H9: 1575 | I9: =IFERROR(H9*VLOOKUP(F9,инфо!$A$15:$C$28,3,FALSE)/1000,0) -> 27.45225 | K9: 9 | L9: 4 | N9: 3210 | O9: 19586 | P9: 0 | S9: =SUM(O9:R9) -> 19586 | Y9: 320 | AC9: 320 | AD9: 160 | AE9: =SUMIFS(инфо!$D$15:$D$28,инфо!$A$15:$A$28,F9) -> 2.06 | AF9: =IF(H9=0,0,N9/H9) -> 2.0380952 | AG9: =AF9-AE9 -> -0.021904762 | AH9: =SUMIFS(инфо!$E$15:$E$28,инфо!$A$15:$A$28,F9) -> 13.28 | AI9: =IF(H9=0,0,S9/H9) -> 12.435556 | AJ9: =AI9-AH9 -> -0.84444444 | AK9: =SUMIFS(инфо!$F$15:$F$28,инфо!$A$15:$A$28,F9) -> 0.205 | AL9: =IF(H9=0,0,Y9/H9) -> 0.2031746 | AM9: =AL9-AK9 -> -0.0018253968 | AN9: =SUMIFS(инфо!$G$15:$G$28,инфо!$A$15:$A$28,F9) -> 0.041 | AO9: =IF(H9=0,0,AA9/H9) -> 0 | AP9: =AO9-AN9 -> -0.041 | AQ9: =SUMIFS(инфо!$H$15:$H$28,инфо!$A$15:$A$28,F9) -> 0 | AR9: =IF(H9=0,0,AC9/H9) -> 0.2031746 | AS9: =AR9-AQ9 -> 0.2031746 | AT9: =SUMIFS(инфо!$I$15:$I$28,инфо!$A$15:$A$28,F9) -> 0.103 | AU9: =IF(H9=0,0,AD9/H9) -> 0.1015873 | AV9: =AU9-AT9 -> -0.0014126984 | AX9: =SUMIFS(инфо!$C$15:$C$28,инфо!$A$15:$A$28,F9)*H9 -> 27452.25
A10: 46072 | B10: 0008 | C10: Линия 1 | D10: ночь | E10: Султанулы | F10: РП коричневый | G10: 35 | H10: 1770 | I10: =IFERROR(H10*VLOOKUP(F10,инфо!$A$15:$C$28,3,FALSE)/1000,0) -> 30.8511 | K10: 4 | L10: 1 | N10: 3538 | O10: 12247 | P10: 9186 | S10: =SUM(O10:R10) -> 21433 | Y10: 350 | AC10: 350 | AE10: =SUMIFS(инфо!$D$15:$D$28,инфо!$A$15:$A$28,F10) -> 2.06 | AF10: =IF(H10=0,0,N10/H10) -> 1.9988701 | AG10: =AF10-AE10 -> -0.061129944 | AH10: =SUMIFS(инфо!$E$15:$E$28,инфо!$A$15:$A$28,F10) -> 13.28 | AI10: =IF(H10=0,0,S10/H10) -> 12.10904 | AJ10: =AI10-AH10 -> -1.1709605 | AK10: =SUMIFS(инфо!$F$15:$F$28,инфо!$A$15:$A$28,F10) -> 0.205 | AL10: =IF(H10=0,0,Y10/H10) -> 0.19774011 | AM10: =AL10-AK10 -> -0.007259887 | AN10: =SUMIFS(инфо!$G$15:$G$28,инфо!$A$15:$A$28,F10) -> 0.041 | AO10: =IF(H10=0,0,AA10/H10) -> 0 | AP10: =AO10-AN10 -> -0.041 | AQ10: =SUMIFS(инфо!$H$15:$H$28,инфо!$A$15:$A$28,F10) -> 0 | AR10: =IF(H10=0,0,AC10/H10) -> 0.19774011 | AS10: =AR10-AQ10 -> 0.19774011 | AT10: =SUMIFS(инфо!$I$15:$I$28,инфо!$A$15:$A$28,F10) -> 0.103 | AU10: =IF(H10=0,0,AD10/H10) -> 0 | AV10: =AU10-AT10 -> -0.103 | AX10: =SUMIFS(инфо!$C$15:$C$28,инфо!$A$15:$A$28,F10)*H10 -> 30851.1
A11: 46073 | B11: 0009 | C11: Линия 1 | D11: день | E11: Дауылбай | F11: РП коричневый | G11: 28 | H11: 1365 | I11: =IFERROR(H11*VLOOKUP(F11,инфо!$A$15:$C$28,3,FALSE)/1000,0) -> 23.79195 | K11: 25 | L11: 4 | N11: 2833 | O11: 8548 | P11: 8573 | S11: =SUM(O11:R11) -> 17121 | Y11: 280 | AC11: 280 | AD11: 140 | AE11: =SUMIFS(инфо!$D$15:$D$28,инфо!$A$15:$A$28,F11) -> 2.06 | AF11: =IF(H11=0,0,N11/H11) -> 2.0754579 | AG11: =AF11-AE11 -> 0.015457875 | AH11: =SUMIFS(инфо!$E$15:$E$28,инфо!$A$15:$A$28,F11) -> 13.28 | AI11: =IF(H11=0,0,S11/H11) -> 12.542857 | AJ11: =AI11-AH11 -> -0.73714286 | AK11: =SUMIFS(инфо!$F$15:$F$28,инфо!$A$15:$A$28,F11) -> 0.205 | AL11: =IF(H11=0,0,Y11/H11) -> 0.20512821 | AM11: =AL11-AK11 -> 0.00012820513 | AN11: =SUMIFS(инфо!$G$15:$G$28,инфо!$A$15:$A$28,F11) -> 0.041 | AO11: =IF(H11=0,0,AA11/H11) -> 0 | AP11: =AO11-AN11 -> -0.041 | AQ11: =SUMIFS(инфо!$H$15:$H$28,инфо!$A$15:$A$28,F11) -> 0 | AR11: =IF(H11=0,0,AC11/H11) -> 0.20512821 | AS11: =AR11-AQ11 -> 0.20512821 | AT11: =SUMIFS(инфо!$I$15:$I$28,инфо!$A$15:$A$28,F11) -> 0.103 | AU11: =IF(H11=0,0,AD11/H11) -> 0.1025641 | AV11: =AU11-AT11 -> -0.00043589744 | AX11: =SUMIFS(инфо!$C$15:$C$28,инфо!$A$15:$A$28,F11)*H11 -> 23791.95
A12: 46073 | B12: 0010 | C12: Линия 1 | D12: ночь | E12: Султанулы | F12: РП красный | G12: 43 | H12: 2096 | I12: =IFERROR(H12*VLOOKUP(F12,инфо!$A$15:$C$28,3,FALSE)/1000,0) -> 36.53328 | K12: 23 | L12: 1 | N12: 4347 | O12: 13442 | P12: 12846 | S12: =SUM(O12:R12) -> 26288 | Y12: 430 | AC12: 430 | AD12: 215 | AE12: =SUMIFS(инфо!$D$15:$D$28,инфо!$A$15:$A$28,F12) -> 2.06 | AF12: =IF(H12=0,0,N12/H12) -> 2.0739504 | AG12: =AF12-AE12 -> 0.013950382 | AH12: =SUMIFS(инфо!$E$15:$E$28,инфо!$A$15:$A$28,F12) -> 13.28 | AI12: =IF(H12=0,0,S12/H12) -> 12.541985 | AJ12: =AI12-AH12 -> -0.73801527 | AK12: =SUMIFS(инфо!$F$15:$F$28,инфо!$A$15:$A$28,F12) -> 0.205 | AL12: =IF(H12=0,0,Y12/H12) -> 0.20515267 | AM12: =AL12-AK12 -> 0.00015267176 | AN12: =SUMIFS(инфо!$G$15:$G$28,инфо!$A$15:$A$28,F12) -> 0.041 | AO12: =IF(H12=0,0,AA12/H12) -> 0 | AP12: =AO12-AN12 -> -0.041 | AQ12: =SUMIFS(инфо!$H$15:$H$28,инфо!$A$15:$A$28,F12) -> 0 | AR12: =IF(H12=0,0,AC12/H12) -> 0.20515267 | AS12: =AR12-AQ12 -> 0.20515267 | AT12: =SUMIFS(инфо!$I$15:$I$28,инфо!$A$15:$A$28,F12) -> 0.103 | AU12: =IF(H12=0,0,AD12/H12) -> 0.10257634 | AV12: =AU12-AT12 -> -0.00042366412 | AX12: =SUMIFS(инфо!$C$15:$C$28,инфо!$A$15:$A$28,F12)*H12 -> 36533.28
A13: =A11+1 -> 46074 | B13: 0011 | C13: Линия 1 | D13: день | E13: Монаев | F13: РП красный | G13: 37 | H13: 1760 | I13: =IFERROR(H13*VLOOKUP(F13,инфо!$A$15:$C$28,3,FALSE)/1000,0) -> 30.6768 | J13: 1700 | K13: 23 | L13: 2 | N13: 3737 | O13: 11620 | P13: 11009 | S13: =SUM(O13:R13) -> 22629 | Y13: 370 | AC13: 370 | AD13: 185 | AE13: =SUMIFS(инфо!$D$15:$D$28,инфо!$A$15:$A$28,F13) -> 2.06 | AF13: =IF(H13=0,0,N13/H13) -> 2.1232955 | AG13: =AF13-AE13 -> 0.063295455 | AH13: =SUMIFS(инфо!$E$15:$E$28,инфо!$A$15:$A$28,F13) -> 13.28 | AI13: =IF(H13=0,0,S13/H13) -> 12.857386 | AJ13: =AI13-AH13 -> -0.42261364 | AK13: =SUMIFS(инфо!$F$15:$F$28,инфо!$A$15:$A$28,F13) -> 0.205 | AL13: =IF(H13=0,0,Y13/H13) -> 0.21022727 | AM13: =AL13-AK13 -> 0.0052272727 | AN13: =SUMIFS(инфо!$G$15:$G$28,инфо!$A$15:$A$28,F13) -> 0.041 | AO13: =IF(H13=0,0,AA13/H13) -> 0 | AP13: =AO13-AN13 -> -0.041 | AQ13: =SUMIFS(инфо!$H$15:$H$28,инфо!$A$15:$A$28,F13) -> 0 | AR13: =IF(H13=0,0,AC13/H13) -> 0.21022727 | AS13: =AR13-AQ13 -> 0.21022727 | AT13: =SUMIFS(инфо!$I$15:$I$28,инфо!$A$15:$A$28,F13) -> 0.103 | AU13: =IF(H13=0,0,AD13/H13) -> 0.10511364 | AV13: =AU13-AT13 -> 0.0021136364 | AX13: =SUMIFS(инфо!$C$15:$C$28,инфо!$A$15:$A$28,F13)*H13 -> 30676.8
A14: =A12+1 -> 46074 | B14: 0012 | C14: Линия 1 | D14: ночь | E14: Дауылбай | F14: РП красный | G14: 41 | H14: 1935 | I14: =IFERROR(H14*VLOOKUP(F14,инфо!$A$15:$C$28,3,FALSE)/1000,0) -> 33.72705 | J14: 1900 | K14: 10 | L14: 8 | N14: 4142 | O14: 12831 | P14: 12243 | S14: =SUM(O14:R14) -> 25074 | Y14: 380 | AC14: 410 | AD14: 205 | AE14: =SUMIFS(инфо!$D$15:$D$28,инфо!$A$15:$A$28,F14) -> 2.06 | AF14: =IF(H14=0,0,N14/H14) -> 2.1405685 | AG14: =AF14-AE14 -> 0.080568475 | AH14: =SUMIFS(инфо!$E$15:$E$28,инфо!$A$15:$A$28,F14) -> 13.28 | AI14: =IF(H14=0,0,S14/H14) -> 12.95814 | AJ14: =AI14-AH14 -> -0.32186047 | AK14: =SUMIFS(инфо!$F$15:$F$28,инфо!$A$15:$A$28,F14) -> 0.205 | AL14: =IF(H14=0,0,Y14/H14) -> 0.19638243 | AM14: =AL14-AK14 -> -0.0086175711 | AN14: =SUMIFS(инфо!$G$15:$G$28,инфо!$A$15:$A$28,F14) -> 0.041 | AO14: =IF(H14=0,0,AA14/H14) -> 0 | AP14: =AO14-AN14 -> -0.041 | AQ14: =SUMIFS(инфо!$H$15:$H$28,инфо!$A$15:$A$28,F14) -> 0 | AR14: =IF(H14=0,0,AC14/H14) -> 0.2118863 | AS14: =AR14-AQ14 -> 0.2118863 | AT14: =SUMIFS(инфо!$I$15:$I$28,инфо!$A$15:$A$28,F14) -> 0.103 | AU14: =IF(H14=0,0,AD14/H14) -> 0.10594315 | AV14: =AU14-AT14 -> 0.0029431525 | AX14: =SUMIFS(инфо!$C$15:$C$28,инфо!$A$15:$A$28,F14)*H14 -> 33727.05
A15: =A13+1 -> 46075 | B15: 0013 | C15: Линия 1 | D15: день | E15: Монаев | F15: РП красный | G15: 31 | H15: 1520 | I15: =IFERROR(H15*VLOOKUP(F15,инфо!$A$15:$C$28,3,FALSE)/1000,0) -> 26.4936 | K15: 7 | L15: 2 | N15: 3127 | O15: 9169 | P15: 9798 | S15: =SUM(O15:R15) -> 18967 | Y15: 310 | AC15: 310 | AD15: 155 | AE15: =SUMIFS(инфо!$D$15:$D$28,инфо!$A$15:$A$28,F15) -> 2.06 | AF15: =IF(H15=0,0,N15/H15) -> 2.0572368 | AG15: =AF15-AE15 -> -0.0027631579 | AH15: =SUMIFS(инфо!$E$15:$E$28,инфо!$A$15:$A$28,F15) -> 13.28 | AI15: =IF(H15=0,0,S15/H15) -> 12.478289 | AJ15: =AI15-AH15 -> -0.80171053 | AK15: =SUMIFS(инфо!$F$15:$F$28,инфо!$A$15:$A$28,F15) -> 0.205 | AL15: =IF(H15=0,0,Y15/H15) -> 0.20394737 | AM15: =AL15-AK15 -> -0.0010526316 | AN15: =SUMIFS(инфо!$G$15:$G$28,инфо!$A$15:$A$28,F15) -> 0.041 | AO15: =IF(H15=0,0,AA15/H15) -> 0 | AP15: =AO15-AN15 -> -0.041 | AQ15: =SUMIFS(инфо!$H$15:$H$28,инфо!$A$15:$A$28,F15) -> 0 | AR15: =IF(H15=0,0,AC15/H15) -> 0.20394737 | AS15: =AR15-AQ15 -> 0.20394737 | AT15: =SUMIFS(инфо!$I$15:$I$28,инфо!$A$15:$A$28,F15) -> 0.103 | AU15: =IF(H15=0,0,AD15/H15) -> 0.10197368 | AV15: =AU15-AT15 -> -0.0010263158 | AX15: =SUMIFS(инфо!$C$15:$C$28,инфо!$A$15:$A$28,F15)*H15 -> 26493.6
A16: 46075 | B16: 0014 | C16: Линия 1 | D16: ночь | E16: Дауылбай | F16: РП красный | G16: 42 | H16: 1985 | I16: =IFERROR(H16*VLOOKUP(F16,инфо!$A$15:$C$28,3,FALSE)/1000,0) -> 34.59855 | K16: 11 | L16: 1 | N16: 4243 | O16: 13418 | P16: 12245 | S16: =SUM(O16:R16) -> 25663 | Y16: 420 | AC16: 420 | AD16: 210 | AE16: =SUMIFS(инфо!$D$15:$D$28,инфо!$A$15:$A$28,F16) -> 2.06 | AF16: =IF(H16=0,0,N16/H16) -> 2.1375315 | AG16: =AF16-AE16 -> 0.077531486 | AH16: =SUMIFS(инфо!$E$15:$E$28,инфо!$A$15:$A$28,F16) -> 13.28 | AI16: =IF(H16=0,0,S16/H16) -> 12.928463 | AJ16: =AI16-AH16 -> -0.35153652 | AK16: =SUMIFS(инфо!$F$15:$F$28,инфо!$A$15:$A$28,F16) -> 0.205 | AL16: =IF(H16=0,0,Y16/H16) -> 0.2115869 | AM16: =AL16-AK16 -> 0.0065869018 | AN16: =SUMIFS(инфо!$G$15:$G$28,инфо!$A$15:$A$28,F16) -> 0.041 | AO16: =IF(H16=0,0,AA16/H16) -> 0 | AP16: =AO16-AN16 -> -0.041 | AQ16: =SUMIFS(инфо!$H$15:$H$28,инфо!$A$15:$A$28,F16) -> 0 | AR16: =IF(H16=0,0,AC16/H16) -> 0.2115869 | AS16: =AR16-AQ16 -> 0.2115869 | AT16: =SUMIFS(инфо!$I$15:$I$28,инфо!$A$15:$A$28,F16) -> 0.103 | AU16: =IF(H16=0,0,AD16/H16) -> 0.10579345 | AV16: =AU16-AT16 -> 0.0027934509 | AX16: =SUMIFS(инфо!$C$15:$C$28,инфо!$A$15:$A$28,F16)*H16 -> 34598.55
A17: =A15+1 -> 46076 | B17: 0015 | C17: Линия 1 | D17: день | E17: Султанулы | F17: РП половинка красный | G17: 19 | H17: 1175 | I17: =IFERROR(H17*VLOOKUP(F17,инфо!$A$15:$C$28,3,FALSE)/1000,0) -> 10.23425 | K17: 8 | L17: 4 | N17: 1916 | O17: 6715 | P17: 4877 | S17: =SUM(O17:R17) -> 11592 | Y17: 190 | AC17: 190 | AE17: =SUMIFS(инфо!$D$15:$D$28,инфо!$A$15:$A$28,F17) -> 1.03 | AF17: =IF(H17=0,0,N17/H17) -> 1.6306383 | AG17: =AF17-AE17 -> 0.6006383 | AH17: =SUMIFS(инфо!$E$15:$E$28,инфо!$A$15:$A$28,F17) -> 664 | AI17: =IF(H17=0,0,S17/H17) -> 9.8655319 | AJ17: =AI17-AH17 -> -654.13447 | AK17: =SUMIFS(инфо!$F$15:$F$28,инфо!$A$15:$A$28,F17) -> 103 | AL17: =IF(H17=0,0,Y17/H17) -> 0.16170213 | AM17: =AL17-AK17 -> -102.8383 | AN17: =SUMIFS(инфо!$G$15:$G$28,инфо!$A$15:$A$28,F17) -> 0.021 | AO17: =IF(H17=0,0,AA17/H17) -> 0 | AP17: =AO17-AN17 -> -0.021 | AQ17: =SUMIFS(инфо!$H$15:$H$28,инфо!$A$15:$A$28,F17) -> 0 | AR17: =IF(H17=0,0,AC17/H17) -> 0.16170213 | AS17: =AR17-AQ17 -> 0.16170213 | AT17: =SUMIFS(инфо!$I$15:$I$28,инфо!$A$15:$A$28,F17) -> 0.051 | AU17: =IF(H17=0,0,AD17/H17) -> 0 | AV17: =AU17-AT17 -> -0.051 | AX17: =SUMIFS(инфо!$C$15:$C$28,инфо!$A$15:$A$28,F17)*H17 -> 10234.25
A18: 46076 | B18: 0016 | C18: Линия 1 | D18: ночь | E18: Монаев | F18: РП половинка красный | G18: 37 | H18: 3145 | I18: =IFERROR(H18*VLOOKUP(F18,инфо!$A$15:$C$28,3,FALSE)/1000,0) -> 27.39295 | N18: 3724 | O18: 11459 | P18: 12099 | S18: =SUM(O18:R18) -> 23558 | Y18: 370 | AC18: 370 | AE18: =SUMIFS(инфо!$D$15:$D$28,инфо!$A$15:$A$28,F18) -> 1.03 | AF18: =IF(H18=0,0,N18/H18) -> 1.1841017 | AG18: =AF18-AE18 -> 0.15410175 | AH18: =SUMIFS(инфо!$E$15:$E$28,инфо!$A$15:$A$28,F18) -> 664 | AI18: =IF(H18=0,0,S18/H18) -> 7.49062 | AJ18: =AI18-AH18 -> -656.50938 | AK18: =SUMIFS(инфо!$F$15:$F$28,инфо!$A$15:$A$28,F18) -> 103 | AL18: =IF(H18=0,0,Y18/H18) -> 0.11764706 | AM18: =AL18-AK18 -> -102.88235 | AN18: =SUMIFS(инфо!$G$15:$G$28,инфо!$A$15:$A$28,F18) -> 0.021 | AO18: =IF(H18=0,0,AA18/H18) -> 0 | AP18: =AO18-AN18 -> -0.021 | AQ18: =SUMIFS(инфо!$H$15:$H$28,инфо!$A$15:$A$28,F18) -> 0 | AR18: =IF(H18=0,0,AC18/H18) -> 0.11764706 | AS18: =AR18-AQ18 -> 0.11764706 | AT18: =SUMIFS(инфо!$I$15:$I$28,инфо!$A$15:$A$28,F18) -> 0.051 | AU18: =IF(H18=0,0,AD18/H18) -> 0 | AV18: =AU18-AT18 -> -0.051 | AX18: =SUMIFS(инфо!$C$15:$C$28,инфо!$A$15:$A$28,F18)*H18 -> 27392.95
A19: =A17+1 -> 46077 | B19: 0017 | C19: Линия 1 | D19: день | E19: Султанулы | F19: РП половинка красный | G19: 27 | H19: 2210 | I19: =IFERROR(H19*VLOOKUP(F19,инфо!$A$15:$C$28,3,FALSE)/1000,0) -> 19.2491 | K19: 5 | L19: 2 | N19: 2727 | O19: 8349 | P19: 8971 | S19: =SUM(O19:R19) -> 17320 | Y19: 135 | AC19: 270 | AE19: =SUMIFS(инфо!$D$15:$D$28,инфо!$A$15:$A$28,F19) -> 1.03 | AF19: =IF(H19=0,0,N19/H19) -> 1.2339367 | AG19: =AF19-AE19 -> 0.20393665 | AH19: =SUMIFS(инфо!$E$15:$E$28,инфо!$A$15:$A$28,F19) -> 664 | AI19: =IF(H19=0,0,S19/H19) -> 7.8371041 | AJ19: =AI19-AH19 -> -656.1629 | AK19: =SUMIFS(инфо!$F$15:$F$28,инфо!$A$15:$A$28,F19) -> 103 | AL19: =IF(H19=0,0,Y19/H19) -> 0.061085973 | AM19: =AL19-AK19 -> -102.93891 | AN19: =SUMIFS(инфо!$G$15:$G$28,инфо!$A$15:$A$28,F19) -> 0.021 | AO19: =IF(H19=0,0,AA19/H19) -> 0 | AP19: =AO19-AN19 -> -0.021 | AQ19: =SUMIFS(инфо!$H$15:$H$28,инфо!$A$15:$A$28,F19) -> 0 | AR19: =IF(H19=0,0,AC19/H19) -> 0.12217195 | AS19: =AR19-AQ19 -> 0.12217195 | AT19: =SUMIFS(инфо!$I$15:$I$28,инфо!$A$15:$A$28,F19) -> 0.051 | AU19: =IF(H19=0,0,AD19/H19) -> 0 | AV19: =AU19-AT19 -> -0.051 | AX19: =SUMIFS(инфо!$C$15:$C$28,инфо!$A$15:$A$28,F19)*H19 -> 19249.1
A20: =A18+1 -> 46077 | B20: 0018 | C20: Линия 1 | D20: ночь | E20: Монаев | F20: РП половинка коричневый | G20: 32 | H20: 3403 | I20: =IFERROR(H20*VLOOKUP(F20,инфо!$A$15:$C$28,3,FALSE)/1000,0) -> 29.64013 | K20: 21 | L20: 3 | N20: 3243 | O20: 10902 | P20: 9629 | S20: =SUM(O20:R20) -> 20531 | Y20: 160 | AC20: 320 | AD20: 160 | AE20: =SUMIFS(инфо!$D$15:$D$28,инфо!$A$15:$A$28,F20) -> 1.03 | AF20: =IF(H20=0,0,N20/H20) -> 0.95298266 | AG20: =AF20-AE20 -> -0.077017338 | AH20: =SUMIFS(инфо!$E$15:$E$28,инфо!$A$15:$A$28,F20) -> 664 | AI20: =IF(H20=0,0,S20/H20) -> 6.033206 | AJ20: =AI20-AH20 -> -657.96679 | AK20: =SUMIFS(инфо!$F$15:$F$28,инфо!$A$15:$A$28,F20) -> 103 | AL20: =IF(H20=0,0,Y20/H20) -> 0.047017338 | AM20: =AL20-AK20 -> -102.95298 | AN20: =SUMIFS(инфо!$G$15:$G$28,инфо!$A$15:$A$28,F20) -> 0.021 | AO20: =IF(H20=0,0,AA20/H20) -> 0 | AP20: =AO20-AN20 -> -0.021 | AQ20: =SUMIFS(инфо!$H$15:$H$28,инфо!$A$15:$A$28,F20) -> 0 | AR20: =IF(H20=0,0,AC20/H20) -> 0.094034675 | AS20: =AR20-AQ20 -> 0.094034675 | AT20: =SUMIFS(инфо!$I$15:$I$28,инфо!$A$15:$A$28,F20) -> 0.051 | AU20: =IF(H20=0,0,AD20/H20) -> 0.047017338 | AV20: =AU20-AT20 -> -0.0039826624 | AX20: =SUMIFS(инфо!$C$15:$C$28,инфо!$A$15:$A$28,F20)*H20 -> 29640.13
A21: =A19+1 -> 46078 | B21: 0019 | C21: Линия 1 | D21: день | E21: Дауылбай | F21: РП половинка | G21: 5 | H21: 426 | I21: =IFERROR(H21*VLOOKUP(F21,инфо!$A$15:$C$28,3,FALSE)/1000,0) -> 3.71046 | J21: 1400 | K21: 5 | M21: 893 | N21: 503 | O21: 3203 | P21: 0 | S21: =SUM(O21:R21) -> 3203 | Y21: 25 | AC21: 50 | AE21: =SUMIFS(инфо!$D$15:$D$28,инфо!$A$15:$A$28,F21) -> 1.03 | AF21: =IF(H21=0,0,N21/H21) -> 1.1807512 | AG21: =AF21-AE21 -> 0.15075117 | AH21: =SUMIFS(инфо!$E$15:$E$28,инфо!$A$15:$A$28,F21) -> 664 | AI21: =IF(H21=0,0,S21/H21) -> 7.5187793 | AJ21: =AI21-AH21 -> -656.48122 | AK21: =SUMIFS(инфо!$F$15:$F$28,инфо!$A$15:$A$28,F21) -> 103 | AL21: =IF(H21=0,0,Y21/H21) -> 0.058685446 | AM21: =AL21-AK21 -> -102.94131 | AN21: =SUMIFS(инфо!$G$15:$G$28,инфо!$A$15:$A$28,F21) -> 0.021 | AO21: =IF(H21=0,0,AA21/H21) -> 0 | AP21: =AO21-AN21 -> -0.021 | AQ21: =SUMIFS(инфо!$H$15:$H$28,инфо!$A$15:$A$28,F21) -> 0 | AR21: =IF(H21=0,0,AC21/H21) -> 0.11737089 | AS21: =AR21-AQ21 -> 0.11737089 | AT21: =SUMIFS(инфо!$I$15:$I$28,инфо!$A$15:$A$28,F21) -> 0.051 | AU21: =IF(H21=0,0,AD21/H21) -> 0 | AV21: =AU21-AT21 -> -0.051 | AX21: =SUMIFS(инфо!$C$15:$C$28,инфо!$A$15:$A$28,F21)*H21 -> 3710.46
A22: =A20+1 -> 46078 | B22: 0020 | C22: Линия 1 | D22: ночь | E22: Султанулы | F22: РП половинка коричневый | G22: 22 | H22: 3310 | I22: =IFERROR(H22*VLOOKUP(F22,инфо!$A$15:$C$28,3,FALSE)/1000,0) -> 28.8301 | J22: 1200 | K22: 3 | L22: 1 | M22: 171 | N22: 2224 | O22: 10264 | P22: 4457 | S22: =SUM(O22:R22) -> 14721 | Y22: 198 | AC22: 220 | AE22: =SUMIFS(инфо!$D$15:$D$28,инфо!$A$15:$A$28,F22) -> 1.03 | AF22: =IF(H22=0,0,N22/H22) -> 0.67190332 | AG22: =AF22-AE22 -> -0.35809668 | AH22: =SUMIFS(инфо!$E$15:$E$28,инфо!$A$15:$A$28,F22) -> 664 | AI22: =IF(H22=0,0,S22/H22) -> 4.447432 | AJ22: =AI22-AH22 -> -659.55257 | AK22: =SUMIFS(инфо!$F$15:$F$28,инфо!$A$15:$A$28,F22) -> 103 | AL22: =IF(H22=0,0,Y22/H22) -> 0.059818731 | AM22: =AL22-AK22 -> -102.94018 | AN22: =SUMIFS(инфо!$G$15:$G$28,инфо!$A$15:$A$28,F22) -> 0.021 | AO22: =IF(H22=0,0,AA22/H22) -> 0 | AP22: =AO22-AN22 -> -0.021 | AQ22: =SUMIFS(инфо!$H$15:$H$28,инфо!$A$15:$A$28,F22) -> 0 | AR22: =IF(H22=0,0,AC22/H22) -> 0.066465257 | AS22: =AR22-AQ22 -> 0.066465257 | AT22: =SUMIFS(инфо!$I$15:$I$28,инфо!$A$15:$A$28,F22) -> 0.051 | AU22: =IF(H22=0,0,AD22/H22) -> 0 | AV22: =AU22-AT22 -> -0.051 | AX22: =SUMIFS(инфо!$C$15:$C$28,инфо!$A$15:$A$28,F22)*H22 -> 28830.1
A23: =A21+1 -> 46079 | B23: 0021 | C23: Линия 1 | D23: день | E23: Дауылбай | F23: РП половинка коричневый | G23: 21 | H23: 2530 | I23: =IFERROR(H23*VLOOKUP(F23,инфо!$A$15:$C$28,3,FALSE)/1000,0) -> 22.0363 | J23: 2200 | K23: 14 | L23: 2 | M23: 159 | N23: 2125 | O23: 6586 | P23: 7227 | S23: =SUM(O23:R23) -> 13813 | Y23: 189 | AC23: 210 | AD23: 30 | AE23: =SUMIFS(инфо!$D$15:$D$28,инфо!$A$15:$A$28,F23) -> 1.03 | AF23: =IF(H23=0,0,N23/H23) -> 0.83992095 | AG23: =AF23-AE23 -> -0.19007905 | AH23: =SUMIFS(инфо!$E$15:$E$28,инфо!$A$15:$A$28,F23) -> 664 | AI23: =IF(H23=0,0,S23/H23) -> 5.4596838 | AJ23: =AI23-AH23 -> -658.54032 | AK23: =SUMIFS(инфо!$F$15:$F$28,инфо!$A$15:$A$28,F23) -> 103 | AL23: =IF(H23=0,0,Y23/H23) -> 0.074703557 | AM23: =AL23-AK23 -> -102.9253 | AN23: =SUMIFS(инфо!$G$15:$G$28,инфо!$A$15:$A$28,F23) -> 0.021 | AO23: =IF(H23=0,0,AA23/H23) -> 0 | AP23: =AO23-AN23 -> -0.021 | AQ23: =SUMIFS(инфо!$H$15:$H$28,инфо!$A$15:$A$28,F23) -> 0 | AR23: =IF(H23=0,0,AC23/H23) -> 0.083003953 | AS23: =AR23-AQ23 -> 0.083003953 | AT23: =SUMIFS(инфо!$I$15:$I$28,инфо!$A$15:$A$28,F23) -> 0.051 | AU23: =IF(H23=0,0,AD23/H23) -> 0.011857708 | AV23: =AU23-AT23 -> -0.039142292 | AX23: =SUMIFS(инфо!$C$15:$C$28,инфо!$A$15:$A$28,F23)*H23 -> 22036.3
A24: =A22+1 -> 46079 | B24: 0022 | C24: Линия 1 | D24: ночь | E24: Султанулы | F24: РП половинка коричневый | G24: 32 | H24: 3595 | I24: =IFERROR(H24*VLOOKUP(F24,инфо!$A$15:$C$28,3,FALSE)/1000,0) -> 31.31245 | J24: 3400 | K24: 11 | L24: 1 | M24: 257 | N24: 3227 | O24: 10905 | P24: 9610 | S24: =SUM(O24:R24) -> 20515 | Y24: 270 | AC24: 320 | AD24: 160 | AE24: =SUMIFS(инфо!$D$15:$D$28,инфо!$A$15:$A$28,F24) -> 1.03 | AF24: =IF(H24=0,0,N24/H24) -> 0.89763561 | AG24: =AF24-AE24 -> -0.13236439 | AH24: =SUMIFS(инфо!$E$15:$E$28,инфо!$A$15:$A$28,F24) -> 664 | AI24: =IF(H24=0,0,S24/H24) -> 5.7065369 | AJ24: =AI24-AH24 -> -658.29346 | AK24: =SUMIFS(инфо!$F$15:$F$28,инфо!$A$15:$A$28,F24) -> 103 | AL24: =IF(H24=0,0,Y24/H24) -> 0.075104312 | AM24: =AL24-AK24 -> -102.9249 | AN24: =SUMIFS(инфо!$G$15:$G$28,инфо!$A$15:$A$28,F24) -> 0.021 | AO24: =IF(H24=0,0,AA24/H24) -> 0 | AP24: =AO24-AN24 -> -0.021 | AQ24: =SUMIFS(инфо!$H$15:$H$28,инфо!$A$15:$A$28,F24) -> 0 | AR24: =IF(H24=0,0,AC24/H24) -> 0.089012517 | AS24: =AR24-AQ24 -> 0.089012517 | AT24: =SUMIFS(инфо!$I$15:$I$28,инфо!$A$15:$A$28,F24) -> 0.051 | AU24: =IF(H24=0,0,AD24/H24) -> 0.044506259 | AV24: =AU24-AT24 -> -0.0064937413 | AX24: =SUMIFS(инфо!$C$15:$C$28,инфо!$A$15:$A$28,F24)*H24 -> 31312.45
A25: =A23+1 -> 46080 | B25: 0023 | C25: Линия 1 | D25: день | E25: Монаев | F25: плоский 10 | G25: 8 | H25: 204 | I25: =IFERROR(H25*VLOOKUP(F25,инфо!$A$15:$C$28,3,FALSE)/1000,0) -> 7.13796 | K25: 7 | L25: 7 | M25: 180 | N25: 812 | O25: 637 | P25: 4366 | S25: 5003 | AC25: 80 | AD25: 7 | AE25: =SUMIFS(инфо!$D$15:$D$28,инфо!$A$15:$A$28,F25) -> 414 | AF25: =IF(H25=0,0,N25/H25) -> 3.9803922 | AG25: =AF25-AE25 -> -410.01961 | AH25: =SUMIFS(инфо!$E$15:$E$28,инфо!$A$15:$A$28,F25) -> 26.73 | AI25: =IF(H25=0,0,S25/H25) -> 24.52451 | AJ25: =AI25-AH25 -> -2.2054902 | AK25: =SUMIFS(инфо!$F$15:$F$28,инфо!$A$15:$A$28,F25) -> 0.413 | AL25: =IF(H25=0,0,Y25/H25) -> 0 | AM25: =AL25-AK25 -> -0.413 | AN25: =SUMIFS(инфо!$G$15:$G$28,инфо!$A$15:$A$28,F25) -> 0 | AO25: =IF(H25=0,0,AA25/H25) -> 0 | AP25: =AO25-AN25 -> 0 | AQ25: =SUMIFS(инфо!$H$15:$H$28,инфо!$A$15:$A$28,F25) -> 0 | AR25: =IF(H25=0,0,AC25/H25) -> 0.39215686 | AS25: =AR25-AQ25 -> 0.39215686 | AT25: =SUMIFS(инфо!$I$15:$I$28,инфо!$A$15:$A$28,F25) -> 0.207 | AU25: =IF(H25=0,0,AD25/H25) -> 0.034313725 | AV25: =AU25-AT25 -> -0.17268627 | AX25: =SUMIFS(инфо!$C$15:$C$28,инфо!$A$15:$A$28,F25)*H25 -> 7137.96
A26: =A24+1 -> 46080 | B26: 0024 | C26: Линия 1 | D26: ночь | E26: Дауылбай | F26: плоский 10 | G26: 42 | H26: 1041 | I26: =IFERROR(H26*VLOOKUP(F26,инфо!$A$15:$C$28,3,FALSE)/1000,0) -> 36.42459 | J26: 650 | K26: 8 | L26: 2 | M26: 91 | N26: 4254 | O26: 10247 | P26: 16661 | S26: =SUM(O26:R26) -> 26908 | Y26: 378 | AC26: 420 | AD26: 205 | AE26: =SUMIFS(инфо!$D$15:$D$28,инфо!$A$15:$A$28,F26) -> 414 | AF26: =IF(H26=0,0,N26/H26) -> 4.0864553 | AG26: =AF26-AE26 -> -409.91354 | AH26: =SUMIFS(инфо!$E$15:$E$28,инфо!$A$15:$A$28,F26) -> 26.73 | AI26: =IF(H26=0,0,S26/H26) -> 25.848223 | AJ26: =AI26-AH26 -> -0.88177714 | AK26: =SUMIFS(инфо!$F$15:$F$28,инфо!$A$15:$A$28,F26) -> 0.413 | AL26: =IF(H26=0,0,Y26/H26) -> 0.36311239 | AM26: =AL26-AK26 -> -0.049887608 | AN26: =SUMIFS(инфо!$G$15:$G$28,инфо!$A$15:$A$28,F26) -> 0 | AO26: =IF(H26=0,0,AA26/H26) -> 0 | AP26: =AO26-AN26 -> 0 | AQ26: =SUMIFS(инфо!$H$15:$H$28,инфо!$A$15:$A$28,F26) -> 0 | AR26: =IF(H26=0,0,AC26/H26) -> 0.40345821 | AS26: =AR26-AQ26 -> 0.40345821 | AT26: =SUMIFS(инфо!$I$15:$I$28,инфо!$A$15:$A$28,F26) -> 0.207 | AU26: =IF(H26=0,0,AD26/H26) -> 0.19692603 | AV26: =AU26-AT26 -> -0.010073967 | AX26: =SUMIFS(инфо!$C$15:$C$28,инфо!$A$15:$A$28,F26)*H26 -> 36424.59
A27: =A25+1 -> 46081 | B27: 0025 | C27: Линия 1 | D27: день | E27: Бекбосынов | F27: плоский 10 | G27: 18 | H27: 799 | I27: =IFERROR(H27*VLOOKUP(F27,инфо!$A$15:$C$28,3,FALSE)/1000,0) -> 27.95701 | J27: 1000 | K27: 0 | L27: 2 | M27: 20 | N27: 3647 | O27: 11527 | P27: 11547 | S27: =SUM(O27:R27) -> 23074 | AC27: 360 | AD27: 180 | AE27: =SUMIFS(инфо!$D$15:$D$28,инфо!$A$15:$A$28,F27) -> 414 | AF27: =IF(H27=0,0,N27/H27) -> 4.5644556 | AG27: =AF27-AE27 -> -409.43554 | AH27: =SUMIFS(инфо!$E$15:$E$28,инфо!$A$15:$A$28,F27) -> 26.73 | AI27: =IF(H27=0,0,S27/H27) -> 28.878598 | AJ27: =AI27-AH27 -> 2.1485982 | AK27: =SUMIFS(инфо!$F$15:$F$28,инфо!$A$15:$A$28,F27) -> 0.413 | AL27: =IF(H27=0,0,Y27/H27) -> 0 | AM27: =AL27-AK27 -> -0.413 | AN27: =SUMIFS(инфо!$G$15:$G$28,инфо!$A$15:$A$28,F27) -> 0 | AO27: =IF(H27=0,0,AA27/H27) -> 0 | AP27: =AO27-AN27 -> 0 | AQ27: =SUMIFS(инфо!$H$15:$H$28,инфо!$A$15:$A$28,F27) -> 0 | AR27: =IF(H27=0,0,AC27/H27) -> 0.4505632 | AS27: =AR27-AQ27 -> 0.4505632 | AT27: =SUMIFS(инфо!$I$15:$I$28,инфо!$A$15:$A$28,F27) -> 0.207 | AU27: =IF(H27=0,0,AD27/H27) -> 0.2252816 | AV27: =AU27-AT27 -> 0.018281602 | AX27: =SUMIFS(инфо!$C$15:$C$28,инфо!$A$15:$A$28,F27)*H27 -> 27957.01
A28: =A26+1 -> 46081 | B28: 0026 | C28: Линия 1 | D28: ночь | E28: Монаев | F28: плоский 10 | G28: 21 | H28: 500 | I28: =IFERROR(H28*VLOOKUP(F28,инфо!$A$15:$C$28,3,FALSE)/1000,0) -> 17.495 | J28: 350 | K28: 1 | M28: 41 | N28: 2127 | O28: 6415 | P28: 7060 | S28: =SUM(O28:R28) -> 13475 | Y28: 189 | AC28: 210 | AD28: 10 | AE28: =SUMIFS(инфо!$D$15:$D$28,инфо!$A$15:$A$28,F28) -> 414 | AF28: =IF(H28=0,0,N28/H28) -> 4.254 | AG28: =AF28-AE28 -> -409.746 | AH28: =SUMIFS(инфо!$E$15:$E$28,инфо!$A$15:$A$28,F28) -> 26.73 | AI28: =IF(H28=0,0,S28/H28) -> 26.95 | AJ28: =AI28-AH28 -> 0.22 | AK28: =SUMIFS(инфо!$F$15:$F$28,инфо!$A$15:$A$28,F28) -> 0.413 | AL28: =IF(H28=0,0,Y28/H28) -> 0.378 | AM28: =AL28-AK28 -> -0.035 | AN28: =SUMIFS(инфо!$G$15:$G$28,инфо!$A$15:$A$28,F28) -> 0 | AO28: =IF(H28=0,0,AA28/H28) -> 0 | AP28: =AO28-AN28 -> 0 | AQ28: =SUMIFS(инфо!$H$15:$H$28,инфо!$A$15:$A$28,F28) -> 0 | AR28: =IF(H28=0,0,AC28/H28) -> 0.42 | AS28: =AR28-AQ28 -> 0.42 | AT28: =SUMIFS(инфо!$I$15:$I$28,инфо!$A$15:$A$28,F28) -> 0.207 | AU28: =IF(H28=0,0,AD28/H28) -> 0.02 | AV28: =AU28-AT28 -> -0.187 | AX28: =SUMIFS(инфо!$C$15:$C$28,инфо!$A$15:$A$28,F28)*H28 -> 17495
A29: =A27+1 -> 46082 | B29: 0027 | C29: Линия 1 | D29: день | E29: Султанулы | F29: плоский 10 | G29: 24 | H29: 580 | I29: =IFERROR(H29*VLOOKUP(F29,инфо!$A$15:$C$28,3,FALSE)/1000,0) -> 20.2942 | J29: 550 | K29: 15 | L29: 4 | M29: 128 | N29: 2412 | O29: 5770 | P29: 9619 | S29: =SUM(O29:R29) -> 15389 | Y29: 216 | AC29: 240 | AD29: 120 | AE29: =SUMIFS(инфо!$D$15:$D$28,инфо!$A$15:$A$28,F29) -> 414 | AF29: =IF(H29=0,0,N29/H29) -> 4.1586207 | AG29: =AF29-AE29 -> -409.84138 | AH29: =SUMIFS(инфо!$E$15:$E$28,инфо!$A$15:$A$28,F29) -> 26.73 | AI29: =IF(H29=0,0,S29/H29) -> 26.532759 | AJ29: =AI29-AH29 -> -0.19724138 | AK29: =SUMIFS(инфо!$F$15:$F$28,инфо!$A$15:$A$28,F29) -> 0.413 | AL29: =IF(H29=0,0,Y29/H29) -> 0.37241379 | AM29: =AL29-AK29 -> -0.040586207 | AN29: =SUMIFS(инфо!$G$15:$G$28,инфо!$A$15:$A$28,F29) -> 0 | AO29: =IF(H29=0,0,AA29/H29) -> 0 | AP29: =AO29-AN29 -> 0 | AQ29: =SUMIFS(инфо!$H$15:$H$28,инфо!$A$15:$A$28,F29) -> 0 | AR29: =IF(H29=0,0,AC29/H29) -> 0.4137931 | AS29: =AR29-AQ29 -> 0.4137931 | AT29: =SUMIFS(инфо!$I$15:$I$28,инфо!$A$15:$A$28,F29) -> 0.207 | AU29: =IF(H29=0,0,AD29/H29) -> 0.20689655 | AV29: =AU29-AT29 -> -0.00010344828 | AX29: =SUMIFS(инфо!$C$15:$C$28,инфо!$A$15:$A$28,F29)*H29 -> 20294.2
A30: =A28+1 -> 46082 | B30: 0028 | C30: Линия 1 | D30: ночь | E30: Бекбосынов | F30: плоский 10 | G30: 47 | H30: 1126 | I30: =IFERROR(H30*VLOOKUP(F30,инфо!$A$15:$C$28,3,FALSE)/1000,0) -> 39.39874 | J30: 1200 | K30: 6 | L30: 2 | M30: 86 | N30: 4737 | O30: 14773 | P30: 15399 | S30: =SUM(O30:R30) -> 30172 | Y30: 423 | AC30: 470 | AD30: 235 | AE30: =SUMIFS(инфо!$D$15:$D$28,инфо!$A$15:$A$28,F30) -> 414 | AF30: =IF(H30=0,0,N30/H30) -> 4.2069272 | AG30: =AF30-AE30 -> -409.79307 | AH30: =SUMIFS(инфо!$E$15:$E$28,инфо!$A$15:$A$28,F30) -> 26.73 | AI30: =IF(H30=0,0,S30/H30) -> 26.795737 | AJ30: =AI30-AH30 -> 0.065737123 | AK30: =SUMIFS(инфо!$F$15:$F$28,инфо!$A$15:$A$28,F30) -> 0.413 | AL30: =IF(H30=0,0,Y30/H30) -> 0.37566607 | AM30: =AL30-AK30 -> -0.037333925 | AN30: =SUMIFS(инфо!$G$15:$G$28,инфо!$A$15:$A$28,F30) -> 0 | AO30: =IF(H30=0,0,AA30/H30) -> 0 | AP30: =AO30-AN30 -> 0 | AQ30: =SUMIFS(инфо!$H$15:$H$28,инфо!$A$15:$A$28,F30) -> 0 | AR30: =IF(H30=0,0,AC30/H30) -> 0.41740675 | AS30: =AR30-AQ30 -> 0.41740675 | AT30: =SUMIFS(инфо!$I$15:$I$28,инфо!$A$15:$A$28,F30) -> 0.207 | AU30: =IF(H30=0,0,AD30/H30) -> 0.20870337 | AV30: =AU30-AT30 -> 0.0017033748 | AX30: =SUMIFS(инфо!$C$15:$C$28,инфо!$A$15:$A$28,F30)*H30 -> 39398.74
A31: =A29+1 -> 46083 | B31: 0029 | C31: Линия 1 | D31: день | E31: Дауылбай | F31: плоский 10 | G31: 30 | H31: 810 | I31: =IFERROR(H31*VLOOKUP(F31,инфо!$A$15:$C$28,3,FALSE)/1000,0) -> 28.3419 | J31: 1000 | K31: 3 | M31: 136 | N31: 3035 | O31: 8337 | P31: 10896 | S31: =SUM(O31:R31) -> 19233 | Y31: 54 | AC31: 290 | AD31: 140 | AE31: =SUMIFS(инфо!$D$15:$D$28,инфо!$A$15:$A$28,F31) -> 414 | AF31: =IF(H31=0,0,N31/H31) -> 3.7469136 | AG31: =AF31-AE31 -> -410.25309 | AH31: =SUMIFS(инфо!$E$15:$E$28,инфо!$A$15:$A$28,F31) -> 26.73 | AI31: =IF(H31=0,0,S31/H31) -> 23.744444 | AJ31: =AI31-AH31 -> -2.9855556 | AK31: =SUMIFS(инфо!$F$15:$F$28,инфо!$A$15:$A$28,F31) -> 0.413 | AL31: =IF(H31=0,0,Y31/H31) -> 0.066666667 | AM31: =AL31-AK31 -> -0.34633333 | AN31: =SUMIFS(инфо!$G$15:$G$28,инфо!$A$15:$A$28,F31) -> 0 | AO31: =IF(H31=0,0,AA31/H31) -> 0 | AP31: =AO31-AN31 -> 0 | AQ31: =SUMIFS(инфо!$H$15:$H$28,инфо!$A$15:$A$28,F31) -> 0 | AR31: =IF(H31=0,0,AC31/H31) -> 0.35802469 | AS31: =AR31-AQ31 -> 0.35802469 | AT31: =SUMIFS(инфо!$I$15:$I$28,инфо!$A$15:$A$28,F31) -> 0.207 | AU31: =IF(H31=0,0,AD31/H31) -> 0.17283951 | AV31: =AU31-AT31 -> -0.034160494 | AX31: =SUMIFS(инфо!$C$15:$C$28,инфо!$A$15:$A$28,F31)*H31 -> 28341.9
A32: 46083 | B32: нет | C32: Линия 1 | D32: ночь | E32: Султанулы | F32: плоский 10 | G32: 0 | H32: 0 | I32: =IFERROR(H32*VLOOKUP(F32,инфо!$A$15:$C$28,3,FALSE)/1000,0) -> 0 | J32: 300 | K32: 7 | L32: 1 | S32: =SUM(O32:R32) -> 0 | AE32: =SUMIFS(инфо!$D$15:$D$28,инфо!$A$15:$A$28,F32) -> 414 | AF32: =IF(H32=0,0,N32/H32) -> 0 | AG32: =AF32-AE32 -> -414 | AH32: =SUMIFS(инфо!$E$15:$E$28,инфо!$A$15:$A$28,F32) -> 26.73 | AI32: =IF(H32=0,0,S32/H32) -> 0 | AJ32: =AI32-AH32 -> -26.73 | AK32: =SUMIFS(инфо!$F$15:$F$28,инфо!$A$15:$A$28,F32) -> 0.413 | AL32: =IF(H32=0,0,Y32/H32) -> 0 | AM32: =AL32-AK32 -> -0.413 | AN32: =SUMIFS(инфо!$G$15:$G$28,инфо!$A$15:$A$28,F32) -> 0 | AO32: =IF(H32=0,0,AA32/H32) -> 0 | AP32: =AO32-AN32 -> 0 | AQ32: =SUMIFS(инфо!$H$15:$H$28,инфо!$A$15:$A$28,F32) -> 0 | AR32: =IF(H32=0,0,AC32/H32) -> 0 | AS32: =AR32-AQ32 -> 0 | AT32: =SUMIFS(инфо!$I$15:$I$28,инфо!$A$15:$A$28,F32) -> 0.207 | AU32: =IF(H32=0,0,AD32/H32) -> 0 | AV32: =AU32-AT32 -> -0.207 | AX32: =SUMIFS(инфо!$C$15:$C$28,инфо!$A$15:$A$28,F32)*H32 -> 0
A33: =A31+1 -> 46084 | B33: 0030 | C33: Линия 1 | D33: день | E33: Монаев | F33: плоский 10 | G33: 16 | H33: 420 | I33: =IFERROR(H33*VLOOKUP(F33,инфо!$A$15:$C$28,3,FALSE)/1000,0) -> 14.6958 | M33: 74 | N33: 1609 | O33: 3675 | P33: 6284 | S33: =SUM(O33:R33) -> 9959 | Y33: 135 | AC33: 30 | AD33: 80 | AE33: =SUMIFS(инфо!$D$15:$D$28,инфо!$A$15:$A$28,F33) -> 414 | AF33: =IF(H33=0,0,N33/H33) -> 3.8309524 | AG33: =AF33-AE33 -> -410.16905 | AH33: =SUMIFS(инфо!$E$15:$E$28,инфо!$A$15:$A$28,F33) -> 26.73 | AI33: =IF(H33=0,0,S33/H33) -> 23.711905 | AJ33: =AI33-AH33 -> -3.0180952 | AK33: =SUMIFS(инфо!$F$15:$F$28,инфо!$A$15:$A$28,F33) -> 0.413 | AL33: =IF(H33=0,0,Y33/H33) -> 0.32142857 | AM33: =AL33-AK33 -> -0.091571429 | AN33: =SUMIFS(инфо!$G$15:$G$28,инфо!$A$15:$A$28,F33) -> 0 | AO33: =IF(H33=0,0,AA33/H33) -> 0 | AP33: =AO33-AN33 -> 0 | AQ33: =SUMIFS(инфо!$H$15:$H$28,инфо!$A$15:$A$28,F33) -> 0 | AR33: =IF(H33=0,0,AC33/H33) -> 0.071428571 | AS33: =AR33-AQ33 -> 0.071428571 | AT33: =SUMIFS(инфо!$I$15:$I$28,инфо!$A$15:$A$28,F33) -> 0.207 | AU33: =IF(H33=0,0,AD33/H33) -> 0.19047619 | AV33: =AU33-AT33 -> -0.01652381 | AX33: =SUMIFS(инфо!$C$15:$C$28,инфо!$A$15:$A$28,F33)*H33 -> 14695.8
A34: =A32+1 -> 46084 | B34: 0031 | C34: Линия 1 | D34: ночь | E34: Дауылбай | F34: плоский 10 | G34: 14 | H34: 330 | I34: =IFERROR(H34*VLOOKUP(F34,инфо!$A$15:$C$28,3,FALSE)/1000,0) -> 11.5467 | J34: 300 | M34: 111 | N34: 1411 | O34: 4479 | P34: 4484 | S34: =SUM(O34:R34) -> 8963 | T34: 100 | U34: 640 | Y34: 126 | AC34: 140 | AD34: 70 | AE34: =SUMIFS(инфо!$D$15:$D$28,инфо!$A$15:$A$28,F34) -> 414 | AF34: =IF(H34=0,0,N34/H34) -> 4.2757576 | AG34: =AF34-AE34 -> -409.72424 | AH34: =SUMIFS(инфо!$E$15:$E$28,инфо!$A$15:$A$28,F34) -> 26.73 | AI34: =IF(H34=0,0,S34/H34) -> 27.160606 | AJ34: =AI34-AH34 -> 0.43060606 | AK34: =SUMIFS(инфо!$F$15:$F$28,инфо!$A$15:$A$28,F34) -> 0.413 | AL34: =IF(H34=0,0,Y34/H34) -> 0.38181818 | AM34: =AL34-AK34 -> -0.031181818 | AN34: =SUMIFS(инфо!$G$15:$G$28,инфо!$A$15:$A$28,F34) -> 0 | AO34: =IF(H34=0,0,AA34/H34) -> 0 | AP34: =AO34-AN34 -> 0 | AQ34: =SUMIFS(инфо!$H$15:$H$28,инфо!$A$15:$A$28,F34) -> 0 | AR34: =IF(H34=0,0,AC34/H34) -> 0.42424242 | AS34: =AR34-AQ34 -> 0.42424242 | AT34: =SUMIFS(инфо!$I$15:$I$28,инфо!$A$15:$A$28,F34) -> 0.207 | AU34: =IF(H34=0,0,AD34/H34) -> 0.21212121 | AV34: =AU34-AT34 -> 0.0051212121 | AX34: =SUMIFS(инфо!$C$15:$C$28,инфо!$A$15:$A$28,F34)*H34 -> 11546.7
A35: =A33+1 -> 46085 | B35: 0032 | C35: Линия 1 | D35: день | E35: Бекбосынов | F35: плоский 10 | G35: 9 | H35: 200 | I35: =IFERROR(H35*VLOOKUP(F35,инфо!$A$15:$C$28,3,FALSE)/1000,0) -> 6.998 | K35: 4 | M35: 13 | N35: 909 | O35: 5118 | P35: 639 | S35: =SUM(O35:R35) -> 5757 | Y35: 81 | AC35: 90 | AD35: 45 | AE35: =SUMIFS(инфо!$D$15:$D$28,инфо!$A$15:$A$28,F35) -> 414 | AF35: =IF(H35=0,0,N35/H35) -> 4.545 | AG35: =AF35-AE35 -> -409.455 | AH35: =SUMIFS(инфо!$E$15:$E$28,инфо!$A$15:$A$28,F35) -> 26.73 | AI35: =IF(H35=0,0,S35/H35) -> 28.785 | AJ35: =AI35-AH35 -> 2.055 | AK35: =SUMIFS(инфо!$F$15:$F$28,инфо!$A$15:$A$28,F35) -> 0.413 | AL35: =IF(H35=0,0,Y35/H35) -> 0.405 | AM35: =AL35-AK35 -> -0.008 | AN35: =SUMIFS(инфо!$G$15:$G$28,инфо!$A$15:$A$28,F35) -> 0 | AO35: =IF(H35=0,0,AA35/H35) -> 0 | AP35: =AO35-AN35 -> 0 | AQ35: =SUMIFS(инфо!$H$15:$H$28,инфо!$A$15:$A$28,F35) -> 0 | AR35: =IF(H35=0,0,AC35/H35) -> 0.45 | AS35: =AR35-AQ35 -> 0.45 | AT35: =SUMIFS(инфо!$I$15:$I$28,инфо!$A$15:$A$28,F35) -> 0.207 | AU35: =IF(H35=0,0,AD35/H35) -> 0.225 | AV35: =AU35-AT35 -> 0.018 | AX35: =SUMIFS(инфо!$C$15:$C$28,инфо!$A$15:$A$28,F35)*H35 -> 6998
A36: =A34+1 -> 46085 | B36: 0033 | C36: Линия 1 | D36: ночь | E36: Монаев | F36: плоский 10 | G36: 23 | H36: 600 | I36: =IFERROR(H36*VLOOKUP(F36,инфо!$A$15:$C$28,3,FALSE)/1000,0) -> 20.994 | J36: 300 | M36: 72 | N36: 2321 | O36: 3834 | P36: 10887 | S36: =SUM(O36:R36) -> 14721 | Y36: 155 | AC36: 230 | AD36: 115 | AE36: =SUMIFS(инфо!$D$15:$D$28,инфо!$A$15:$A$28,F36) -> 414 | AF36: =IF(H36=0,0,N36/H36) -> 3.8683333 | AG36: =AF36-AE36 -> -410.13167 | AH36: =SUMIFS(инфо!$E$15:$E$28,инфо!$A$15:$A$28,F36) -> 26.73 | AI36: =IF(H36=0,0,S36/H36) -> 24.535 | AJ36: =AI36-AH36 -> -2.195 | AK36: =SUMIFS(инфо!$F$15:$F$28,инфо!$A$15:$A$28,F36) -> 0.413 | AL36: =IF(H36=0,0,Y36/H36) -> 0.25833333 | AM36: =AL36-AK36 -> -0.15466667 | AN36: =SUMIFS(инфо!$G$15:$G$28,инфо!$A$15:$A$28,F36) -> 0 | AO36: =IF(H36=0,0,AA36/H36) -> 0 | AP36: =AO36-AN36 -> 0 | AQ36: =SUMIFS(инфо!$H$15:$H$28,инфо!$A$15:$A$28,F36) -> 0 | AR36: =IF(H36=0,0,AC36/H36) -> 0.38333333 | AS36: =AR36-AQ36 -> 0.38333333 | AT36: =SUMIFS(инфо!$I$15:$I$28,инфо!$A$15:$A$28,F36) -> 0.207 | AU36: =IF(H36=0,0,AD36/H36) -> 0.19166667 | AV36: =AU36-AT36 -> -0.015333333 | AX36: =SUMIFS(инфо!$C$15:$C$28,инфо!$A$15:$A$28,F36)*H35 -> 6998
A37: =A35+1 -> 46086 | B37: 0034 | C37: Линия 1 | D37: день | E37: Султанулы | F37: плоский 10 | G37: 11 | H37: 214 | I37: =IFERROR(H37*VLOOKUP(F37,инфо!$A$15:$C$28,3,FALSE)/1000,0) -> 7.48786 | J37: 400 | K37: 2 | L37: 1 | M37: 25 | N37: 1113 | O37: 1279 | P37: 5762 | S37: =SUM(O37:R37) -> 7041 | T37: 55 | Y37: 110 | AC37: 110 | AE37: =SUMIFS(инфо!$D$15:$D$28,инфо!$A$15:$A$28,F37) -> 414 | AF37: =IF(H37=0,0,N37/H37) -> 5.2009346 | AG37: =AF37-AE37 -> -408.79907 | AH37: =SUMIFS(инфо!$E$15:$E$28,инфо!$A$15:$A$28,F37) -> 26.73 | AI37: =IF(H37=0,0,S37/H37) -> 32.901869 | AJ37: =AI37-AH37 -> 6.1718692 | AK37: =SUMIFS(инфо!$F$15:$F$28,инфо!$A$15:$A$28,F37) -> 0.413 | AL37: =IF(H37=0,0,Y37/H37) -> 0.51401869 | AM37: =AL37-AK37 -> 0.10101869 | AN37: =SUMIFS(инфо!$G$15:$G$28,инфо!$A$15:$A$28,F37) -> 0 | AO37: =IF(H37=0,0,AA37/H37) -> 0 | AP37: =AO37-AN37 -> 0 | AQ37: =SUMIFS(инфо!$H$15:$H$28,инфо!$A$15:$A$28,F37) -> 0 | AR37: =IF(H36=0,0,AC37/H36) -> 0.18333333 | AS37: =AR37-AQ37 -> 0.18333333 | AT37: =SUMIFS(инфо!$I$15:$I$28,инфо!$A$15:$A$28,F37) -> 0.207 | AU37: =IF(H37=0,0,AD37/H37) -> 0 | AV37: =AU37-AT37 -> -0.207 | AX37: =SUMIFS(инфо!$C$15:$C$28,инфо!$A$15:$A$28,F37)*H36 -> 20994
A38: 46087 | B38: 0035 | C38: Линия 1 | D38: день | E38: Дауылбай | F38: плоский 10 | G38: 25 | H38: 590 | I38: =IFERROR(H38*VLOOKUP(F38,инфо!$A$15:$C$28,3,FALSE)/1000,0) -> 20.6441 | J38: 550 | M38: 170 | N38: 2644 | P38: 15653 | S38: =SUM(O38:R38) -> 15653 | Y38: 250 | AC38: 250 | AD38: 125 | AE38: =SUMIFS(инфо!$D$15:$D$28,инфо!$A$15:$A$28,F38) -> 414 | AF38: =IF(H38=0,0,N38/H38) -> 4.4813559 | AG38: =AF38-AE38 -> -409.51864 | AH38: =SUMIFS(инфо!$E$15:$E$28,инфо!$A$15:$A$28,F38) -> 26.73 | AI38: =IF(H38=0,0,S38/H38) -> 26.530508 | AJ38: =AI38-AH38 -> -0.19949153 | AK38: =SUMIFS(инфо!$F$15:$F$28,инфо!$A$15:$A$28,F38) -> 0.413 | AL38: =IF(H38=0,0,Y38/H38) -> 0.42372881 | AM38: =AL38-AK38 -> 0.010728814 | AN38: =SUMIFS(инфо!$G$15:$G$28,инфо!$A$15:$A$28,F38) -> 0 | AO38: =IF(H38=0,0,AA38/H38) -> 0 | AP38: =AO38-AN38 -> 0 | AQ38: =SUMIFS(инфо!$H$15:$H$28,инфо!$A$15:$A$28,F38) -> 0 | AR38: =IF(H37=0,0,AC38/H37) -> 1.1682243 | AS38: =AR38-AQ38 -> 1.1682243 | AT38: =SUMIFS(инфо!$I$15:$I$28,инфо!$A$15:$A$28,F38) -> 0.207 | AU38: =IF(H38=0,0,AD38/H38) -> 0.21186441 | AV38: =AU38-AT38 -> 0.0048644068 | AX38: =SUMIFS(инфо!$C$15:$C$28,инфо!$A$15:$A$28,F38)*H37 -> 7487.86
A39: =A37+1 -> 46087 | B39: 0036 | C39: Линия 1 | D39: ночь | E39: Султанулы | F39: плоский 10 | G39: 43 | H39: 1045 | I39: =IFERROR(H39*VLOOKUP(F39,инфо!$A$15:$C$28,3,FALSE)/1000,0) -> 36.56455 | J39: 950 | K39: 1 | M39: 765 | N39: 4340 | O39: 27583 | S39: =SUM(O39:R39) -> 27583 | Y39: 430 | AC39: 430 | AD39: 215 | AE39: =SUMIFS(инфо!$D$15:$D$28,инфо!$A$15:$A$28,F39) -> 414 | AF39: =IF(H39=0,0,N39/H39) -> 4.15311 | AG39: =AF39-AE39 -> -409.84689 | AH39: =SUMIFS(инфо!$E$15:$E$28,инфо!$A$15:$A$28,F39) -> 26.73 | AI39: =IF(H39=0,0,S39/H39) -> 26.395215 | AJ39: =AI39-AH39 -> -0.33478469 | AK39: =SUMIFS(инфо!$F$15:$F$28,инфо!$A$15:$A$28,F39) -> 0.413 | AL39: =IF(H39=0,0,Y39/H39) -> 0.41148325 | AM39: =AL39-AK39 -> -0.0015167464 | AN39: =SUMIFS(инфо!$G$15:$G$28,инфо!$A$15:$A$28,F39) -> 0 | AO39: =IF(H39=0,0,AA39/H39) -> 0 | AP39: =AO39-AN39 -> 0 | AQ39: =SUMIFS(инфо!$H$15:$H$28,инфо!$A$15:$A$28,F39) -> 0 | AR39: =IF(H38=0,0,AC39/H38) -> 0.72881356 | AS39: =AR39-AQ39 -> 0.72881356 | AT39: =SUMIFS(инфо!$I$15:$I$28,инфо!$A$15:$A$28,F39) -> 0.207 | AU39: =IF(H39=0,0,AD39/H39) -> 0.20574163 | AV39: =AU39-AT39 -> -0.0012583732 | AX39: =SUMIFS(инфо!$C$15:$C$28,инфо!$A$15:$A$28,F39)*H38 -> 20644.1
A40: =A38+1 -> 46088 | B40: 0037 | C40: Линия 1 | D40: день | E40: Монаев | F40: плоский 8 | G40: 34 | H40: 960 | I40: =IFERROR(H40*VLOOKUP(F40,инфо!$A$15:$C$28,3,FALSE)/1000,0) -> 26.8704 | J40: 900 | L40: 4 | M40: 39 | N40: 3447 | P40: 21822 | S40: =SUM(O40:R40) -> 21822 | Y40: 340 | AC40: 340 | AD40: 170 | AE40: =SUMIFS(инфо!$D$15:$D$28,инфо!$A$15:$A$28,F40) -> 3.31 | AF40: =IF(H40=0,0,N40/H40) -> 3.590625 | AG40: =AF40-AE40 -> 0.280625 | AH40: =SUMIFS(инфо!$E$15:$E$28,инфо!$A$15:$A$28,F40) -> 2138 | AI40: =IF(H40=0,0,S40/H40) -> 22.73125 | AJ40: =AI40-AH40 -> -2115.2688 | AK40: =SUMIFS(инфо!$F$15:$F$28,инфо!$A$15:$A$28,F40) -> 0.331 | AL40: =IF(H40=0,0,Y40/H40) -> 0.35416667 | AM40: =AL40-AK40 -> 0.023166667 | AN40: =SUMIFS(инфо!$G$15:$G$28,инфо!$A$15:$A$28,F40) -> 0 | AO40: =IF(H40=0,0,AA40/H40) -> 0 | AP40: =AO40-AN40 -> 0 | AQ40: =SUMIFS(инфо!$H$15:$H$28,инфо!$A$15:$A$28,F40) -> 0 | AR40: =IF(H39=0,0,AC40/H39) -> 0.32535885 | AS40: =AR40-AQ40 -> 0.32535885 | AT40: =SUMIFS(инфо!$I$15:$I$28,инфо!$A$15:$A$28,F40) -> 0.165 | AU40: =IF(H40=0,0,AD40/H40) -> 0.17708333 | AV40: =AU40-AT40 -> 0.012083333 | AX40: =SUMIFS(инфо!$C$15:$C$28,инфо!$A$15:$A$28,F40)*H39 -> 29249.55
...

Sheet Простои
A1: Дата | B1: Мастер | C1: Cмена | D1: Причина простоя | E1: Начало | F1: Конец | G1: Время | I1: Дата | J1: Мастер | K1: Cмена | L1: Причина простоя | M1: Начало | N1: Конец | O1: Время
A2: 46082 | B2: Султанулы | C2: день | D2: Поменяли (сукно).Для инфармций:Поменяли форматный барабан,поменяли сукно валик рассыпался подшипник,поменяли нож,чистили желоб,чистили сплинкерную трубу,убрали вокруг машины | E2: 0.33333333 | F2: 0.4875 | G2: =F2-E2 -> 0.15416667 | I2: 46082 | K2: ночь | M2: 0 | N2: 0 | O2: =N2-M2 -> 0
E3: 0 | F3: 0 | G3: =F3-E3 -> 0 | M3: 0 | N3: 0 | O3: =N3-M3 -> 0
E4: 0 | F4: 0 | G4: =F4-E4 -> 0 | M4: 0 | N4: 0 | O4: =N4-M4 -> 0
E5: 0 | F5: 0 | G5: =F5-E5 -> 0 | M5: 0 | N5: 0 | O5: =N5-M5 -> 0
E6: 0 | F6: 0 | G6: =F6-E6 -> 0 | M6: 0 | N6: 0 | O6: =N6-M6 -> 0
E7: 0 | F7: 0 | G7: =F7-E7 -> 0 | M7: 0 | N7: 0 | O7: =N7-M7 -> 0
E8: 0 | F8: 0 | G8: =F8-E8 -> 0 | M8: 0 | N8: 0 | O8: =N8-M8 -> 0
E9: 0 | F9: 0 | G9: =F9-E9 -> 0 | M9: 0 | N9: 0 | O9: =N9-M9 -> 0
G10: =SUM(G2:G9) -> 0.15416667 | O10: =SUM(O2,O9) -> 0
A11: =A2+1 -> 46083 | B11: Дауылбай | C11: день | D11: Передвинулй спомагателный трубовалик возле барабана | E11: 0.70486111 | F11: 0.72222222 | G11: =F11-E11 -> 0.017361111 | I11: =I2+1 -> 46083 | J11: Султанулы | K11: ночь | L11: Санитарный день! Сняли все с/цилиндр и очистили все ванны.Очистили премный каропку.Почистили гомагинизатор и желоб.Сплинкерную трубу очистили кислатой.Заменили №2-3 с/цилиндр №1 с/цилиндр промыли и поставили обратно.Очистили верхний и нижний вакуум.Почистили ресивер.Подняли падемник на валнировке и очистили.Прочистили вокруг машины и вакуумный насос,трубы,двигатель,редуктор протрёли.Во всём цехе сделали уборку. | M11: 0.79166667 | N11: 0.33333333 | O11: 13.541667
E12: 0 | F12: 0 | G12: =F12-E12 -> 0 | M12: 0 | N12: 0 | O12: =N12-M12 -> 0
E13: 0 | F13: 0 | G13: =F13-E13 -> 0 | M13: 0 | N13: 0 | O13: =N13-M13 -> 0
E14: 0 | F14: 0 | G14: =F14-E14 -> 0 | M14: 0 | N14: 0 | O14: =N14-M14 -> 0
E15: 0 | F15: 0 | G15: =F15-E15 -> 0 | M15: 0 | N15: 0 | O15: =N15-M15 -> 0
E16: 0 | F16: 0 | G16: =F16-E16 -> 0 | M16: 0 | N16: 0 | O16: =N16-M16 -> 0
E17: 0 | F17: 0 | G17: =F17-E17 -> 0 | M17: 0 | N17: 0 | O17: =N17-M17 -> 0
E18: 0 | F18: 0 | G18: =F18-E18 -> 0 | M18: 0 | N18: 0 | O18: =N18-M18 -> 0
G19: =SUM(G11,G18) -> 0.017361111 | O19: =SUM(O11,O18) -> 13.541667
A20: =A11+1 -> 46084 | B20: Монаев | C20: день | D20: Замена ф/барабан,варили редуктор натяжка т/сукно,замена подшипник поддерживающие т/валик | E20: 0.33333333 | F20: 0.47916667 | G20: =F20-E20 -> 0.14583333 | I20: =I11+1 -> 46084 | J20: Дауылбай | K20: ночь | L20: выробатали массу промылй тех-сукно на холостом | M20: 0.80902778 | N20: 0.83680556 | O20: =N20-M20 -> 0.027777778
D21: 2 лопастной мешалке срезло шпонка,заменили | E21: 0.52083333 | F21: 0.53958333 | G21: =F21-E21 -> 0.01875 | L21: выроботалй массу останавилй машину на переделку вакумнгых труб | M21: 0.90972222 | N21: 1.0243056 | O21: =N21-M21 -> 0.11458333
E22: 0 | F22: 0 | G22: =F22-E22 -> 0 | L22: Ершеня начил опят промылй кислотолй формовачный барабан поменялй | M22: 0.1875 | N22: 0.20138889 | O22: =N22-M22 -> 0.013888889
E23: 0 | F23: 0 | G23: =F23-E23 -> 0 | L23: останавилй сливалй один замес старую массу | M23: 0.20833333 | N23: 0.24305556 | O23: =N23-M23 -> 0.034722222
E24: 0 | F24: 0 | G24: =F24-E24 -> 0 | L24: выролботалй массу останавилй машину промываем техсукно ерщеня не отходить. | M24: 0.26388889 | N24: 0.33333333 | O24: =N24-M24 -> 0.069444444
E25: 0 | F25: 0 | G25: =F25-E25 -> 0 | M25: 0 | N25: 0 | O25: =N25-M25 -> 0
E26: 0 | F26: 0 | G26: =F26-E26 -> 0 | M26: 0 | N26: 0 | O26: =N26-M26 -> 0
E27: 0 | F27: 0 | G27: =F27-E27 -> 0 | M27: 0 | N27: 0 | O27: =N27-M27 -> 0
G28: =SUM(G20:G27) -> 0.16458333 | O28: =SUM(O20:O27) -> 0.26041667
A29: =A20+1 -> 46085 | B29: Бекбосынов | C29: день | D29: поменяли грязный 1 насос и 2 раза переделовали вакумный насос | E29: 0.33333333 | F29: 0.6 | G29: =F29-E29 -> 0.26666667 | I29: =I20+1 -> 46085 | J29: Монаев | K29: ночь | L29: промывка т/сукно | M29: 0.95833333 | N29: 0 | O29: 0.020833333
E30: 0 | F30: 0 | G30: =F30-E30 -> 0 | L30: повторно промывка т/сукно из-за ершение | M30: 0.013888889 | N30: 0.041666667 | O30: =N30-M30 -> 0.027777778
E31: 0 | F31: 0 | G31: =F31-E31 -> 0 | L31: из-за ершение останавили машину,промывали ф/барабан с кислотой | M31: 0.083333333 | N31: 0.125 | O31: =N31-M31 -> 0.041666667
E32: 0 | F32: 0 | G32: =F32-E32 -> 0 | M32: 0 | N32: 0 | O32: =N32-M32 -> 0
E33: 0 | F33: 0 | G33: =F33-E33 -> 0 | M33: 0 | N33: 0 | O33: =N33-M33 -> 0
E34: 0 | F34: 0 | G34: =F34-E34 -> 0 | M34: 0 | N34: 0 | O34: =N34-M34 -> 0
E35: 0 | F35: 0 | G35: =F35-E35 -> 0 | M35: 0 | N35: 0 | O35: =N35-M35 -> 0
E36: 0 | F36: 0 | G36: =F36-E36 -> 0 | M36: 0 | N36: 0 | O36: =N36-M36 -> 0
G37: =SUM(G29,G36) -> 0.26666667 | O37: =SUM(O29:O36) -> 0.090277778
A38: =A29+1 -> 46086 | B38: Султанулы | C38: день | D38: Сукно мыли, поменяли трос формовочный барабана | E38: 0.53472222 | F38: 0.57777778 | G38: =F38-E38 -> 0.043055556 | I38: =I29+1 -> 46086 | J38: Дауылбай | K38: ночь | M38: 0 | N38: 0 | O38: =N38-M38 -> 0
D39: Поменяли №2-с/цилиндр,чистили сплинкерную трубу и желоб | E39: 0.61875 | F39: 0.64444444 | G39: =F39-E39 -> 0.025694444 | M39: 0 | N39: 0 | O39: =N39-M39 -> 0
D40: Очистка машины | E40: 0.75555556 | F40: 0.79166667 | G40: =F40-E40 -> 0.036111111 | M40: 0 | N40: 0 | O40: =N40-M40 -> 0
...

Sheet сырье
A1: дата | B1: ЦЕМЕНТ, приход | F1: ЦЕМЕНТ, факт остаток после замера | J1: ЦЕМЕНТ, учет остаток | O1: дата | P1: АСБЕСТ, приход | U1: АСБЕСТ, факт остаток
B2: силос 1 | C2: силос 2 | D2: силос 3 | E2: силос 4 | F2: силос 1 | G2: силос 2 | H2: силос 3 | I2: силос 4 | J2: силос 1 | K2: силос 2 | L2: силос 3 | M2: силос 4 | P2: А5-65 | Q2: А4-20 | R2: А6-45 | S2: ОМ | T2: всего | U2: А5-65 | V2: А4-20 | W2: А6-45 | X2: ОМ | Y2: всего
F3: 1729 | G3: 12455 | H3: 0 | I3: 14417 | J3: 1729 | K3: 12455 | L3: 0 | M3: 14417 | U3: 759900 | V3: 0 | W3: 0 | X3: 0 | Y3: =SUM(U3:X3) -> 759900
A4: 46023 | F4: =F3 -> 1729 | G4: =G3 -> 12455 | H4: =H3 -> 0 | I4: =I3 -> 14417 | J4: =J3+B4-SUMIFS(рапорт!$O:$O,рапорт!$A:$A,A4)-SUMIFS(рапорт!$U:$U,рапорт!$A:$A,A4)/4 -> 1729 | K4: =K3+C4-SUMIFS(рапорт!$P:$P,рапорт!$A:$A,A4)-SUMIFS(рапорт!$U:$U,рапорт!$A:$A,A4)/4 -> 12455 | L4: =L3+D4-SUMIFS(рапорт!$Q:$Q,рапорт!$A:$A,A4)-SUMIFS(рапорт!$U:$U,рапорт!$A:$A,A4)/4 -> 0 | M4: =M3+E4-SUMIFS(рапорт!$R:$R,рапорт!$A:$A,A4)-SUMIFS(рапорт!$U:$U,рапорт!$A:$A,A4)/4 -> 14417 | O4: 46023 | T4: =SUM(P4:S4) -> 0 | U4: =U3 -> 759900 | V4: =V3 -> 0 | W4: =W3 -> 0 | X4: =X3 -> 0 | Y4: =SUM(U4:X4) -> 759900
A5: 46024 | F5: =F4 -> 1729 | G5: =G4 -> 12455 | H5: =H4 -> 0 | I5: =I4 -> 14417 | J5: =J4+B5-SUMIFS(рапорт!$O:$O,рапорт!$A:$A,A5)-SUMIFS(рапорт!$U:$U,рапорт!$A:$A,A5)/4 -> 1729 | K5: =K4+C5-SUMIFS(рапорт!$P:$P,рапорт!$A:$A,A5)-SUMIFS(рапорт!$U:$U,рапорт!$A:$A,A5)/4 -> 12455 | L5: =L4+D5-SUMIFS(рапорт!$Q:$Q,рапорт!$A:$A,A5)-SUMIFS(рапорт!$U:$U,рапорт!$A:$A,A5)/4 -> 0 | M5: =M4+E5-SUMIFS(рапорт!$R:$R,рапорт!$A:$A,A5)-SUMIFS(рапорт!$U:$U,рапорт!$A:$A,A5)/4 -> 14417 | O5: 46024 | T5: =SUM(P5:S5) -> 0 | U5: =U4 -> 759900 | V5: =V4 -> 0 | W5: =W4 -> 0 | X5: =X4 -> 0 | Y5: =SUM(U5:X5) -> 759900
A6: 46025 | F6: =F5 -> 1729 | G6: =G5 -> 12455 | H6: =H5 -> 0 | I6: =I5 -> 14417 | J6: =J5+B6-SUMIFS(рапорт!$O:$O,рапорт!$A:$A,A6)-SUMIFS(рапорт!$U:$U,рапорт!$A:$A,A6)/4 -> 1729 | K6: =K5+C6-SUMIFS(рапорт!$P:$P,рапорт!$A:$A,A6)-SUMIFS(рапорт!$U:$U,рапорт!$A:$A,A6)/4 -> 12455 | L6: =L5+D6-SUMIFS(рапорт!$Q:$Q,рапорт!$A:$A,A6)-SUMIFS(рапорт!$U:$U,рапорт!$A:$A,A6)/4 -> 0 | M6: =M5+E6-SUMIFS(рапорт!$R:$R,рапорт!$A:$A,A6)-SUMIFS(рапорт!$U:$U,рапорт!$A:$A,A6)/4 -> 14417 | O6: 46025 | T6: =SUM(P6:S6) -> 0 | U6: =U5 -> 759900 | V6: =V5 -> 0 | W6: =W5 -> 0 | X6: =X5 -> 0 | Y6: =SUM(U6:X6) -> 759900
A7: 46026 | F7: =F6 -> 1729 | G7: =G6 -> 12455 | H7: =H6 -> 0 | I7: =I6 -> 14417 | J7: =J6+B7-SUMIFS(рапорт!$O:$O,рапорт!$A:$A,A7)-SUMIFS(рапорт!$U:$U,рапорт!$A:$A,A7)/4 -> 1729 | K7: =K6+C7-SUMIFS(рапорт!$P:$P,рапорт!$A:$A,A7)-SUMIFS(рапорт!$U:$U,рапорт!$A:$A,A7)/4 -> 12455 | L7: =L6+D7-SUMIFS(рапорт!$Q:$Q,рапорт!$A:$A,A7)-SUMIFS(рапорт!$U:$U,рапорт!$A:$A,A7)/4 -> 0 | M7: =M6+E7-SUMIFS(рапорт!$R:$R,рапорт!$A:$A,A7)-SUMIFS(рапорт!$U:$U,рапорт!$A:$A,A7)/4 -> 14417 | O7: 46026 | T7: =SUM(P7:S7) -> 0 | U7: =U6 -> 759900 | V7: =V6 -> 0 | W7: =W6 -> 0 | X7: =X6 -> 0 | Y7: =SUM(U7:X7) -> 759900
A8: 46027 | F8: =F7 -> 1729 | G8: =G7 -> 12455 | H8: =H7 -> 0 | I8: =I7 -> 14417 | J8: =J7+B8-SUMIFS(рапорт!$O:$O,рапорт!$A:$A,A8)-SUMIFS(рапорт!$U:$U,рапорт!$A:$A,A8)/4 -> 1729 | K8: =K7+C8-SUMIFS(рапорт!$P:$P,рапорт!$A:$A,A8)-SUMIFS(рапорт!$U:$U,рапорт!$A:$A,A8)/4 -> 12455 | L8: =L7+D8-SUMIFS(рапорт!$Q:$Q,рапорт!$A:$A,A8)-SUMIFS(рапорт!$U:$U,рапорт!$A:$A,A8)/4 -> 0 | M8: =M7+E8-SUMIFS(рапорт!$R:$R,рапорт!$A:$A,A8)-SUMIFS(рапорт!$U:$U,рапорт!$A:$A,A8)/4 -> 14417 | O8: 46027 | T8: =SUM(P8:S8) -> 0 | U8: =U7 -> 759900 | V8: =V7 -> 0 | W8: =W7 -> 0 | X8: =X7 -> 0 | Y8: =SUM(U8:X8) -> 759900
A9: 46028 | F9: =F8 -> 1729 | G9: =G8 -> 12455 | H9: =H8 -> 0 | I9: =I8 -> 14417 | J9: =J8+B9-SUMIFS(рапорт!$O:$O,рапорт!$A:$A,A9)-SUMIFS(рапорт!$U:$U,рапорт!$A:$A,A9)/4 -> 1729 | K9: =K8+C9-SUMIFS(рапорт!$P:$P,рапорт!$A:$A,A9)-SUMIFS(рапорт!$U:$U,рапорт!$A:$A,A9)/4 -> 12455 | L9: =L8+D9-SUMIFS(рапорт!$Q:$Q,рапорт!$A:$A,A9)-SUMIFS(рапорт!$U:$U,рапорт!$A:$A,A9)/4 -> 0 | M9: =M8+E9-SUMIFS(рапорт!$R:$R,рапорт!$A:$A,A9)-SUMIFS(рапорт!$U:$U,рапорт!$A:$A,A9)/4 -> 14417 | O9: 46028 | T9: =SUM(P9:S9) -> 0 | U9: =U8 -> 759900 | V9: =V8 -> 0 | W9: =W8 -> 0 | X9: =X8 -> 0 | Y9: =SUM(U9:X9) -> 759900
A10: 46029 | F10: =F9 -> 1729 | G10: =G9 -> 12455 | H10: =H9 -> 0 | I10: =I9 -> 14417 | J10: =J9+B10-SUMIFS(рапорт!$O:$O,рапорт!$A:$A,A10)-SUMIFS(рапорт!$U:$U,рапорт!$A:$A,A10)/4 -> 1729 | K10: =K9+C10-SUMIFS(рапорт!$P:$P,рапорт!$A:$A,A10)-SUMIFS(рапорт!$U:$U,рапорт!$A:$A,A10)/4 -> 12455 | L10: =L9+D10-SUMIFS(рапорт!$Q:$Q,рапорт!$A:$A,A10)-SUMIFS(рапорт!$U:$U,рапорт!$A:$A,A10)/4 -> 0 | M10: =M9+E10-SUMIFS(рапорт!$R:$R,рапорт!$A:$A,A10)-SUMIFS(рапорт!$U:$U,рапорт!$A:$A,A10)/4 -> 14417 | O10: 46029 | T10: =SUM(P10:S10) -> 0 | U10: =U9 -> 759900 | V10: =V9 -> 0 | W10: =W9 -> 0 | X10: =X9 -> 0 | Y10: =SUM(U10:X10) -> 759900
A11: 46030 | F11: =F10 -> 1729 | G11: =G10 -> 12455 | H11: =H10 -> 0 | I11: =I10 -> 14417 | J11: =J10+B11-SUMIFS(рапорт!$O:$O,рапорт!$A:$A,A11)-SUMIFS(рапорт!$U:$U,рапорт!$A:$A,A11)/4 -> 1729 | K11: =K10+C11-SUMIFS(рапорт!$P:$P,рапорт!$A:$A,A11)-SUMIFS(рапорт!$U:$U,рапорт!$A:$A,A11)/4 -> 12455 | L11: =L10+D11-SUMIFS(рапорт!$Q:$Q,рапорт!$A:$A,A11)-SUMIFS(рапорт!$U:$U,рапорт!$A:$A,A11)/4 -> 0 | M11: =M10+E11-SUMIFS(рапорт!$R:$R,рапорт!$A:$A,A11)-SUMIFS(рапорт!$U:$U,рапорт!$A:$A,A11)/4 -> 14417 | O11: 46030 | T11: =SUM(P11:S11) -> 0 | U11: =U10 -> 759900 | V11: =V10 -> 0 | W11: =W10 -> 0 | X11: =X10 -> 0 | Y11: =SUM(U11:X11) -> 759900
A12: 46031 | F12: =F11 -> 1729 | G12: =G11 -> 12455 | H12: =H11 -> 0 | I12: =I11 -> 14417 | J12: =J11+B12-SUMIFS(рапорт!$O:$O,рапорт!$A:$A,A12)-SUMIFS(рапорт!$U:$U,рапорт!$A:$A,A12)/4 -> 1729 | K12: =K11+C12-SUMIFS(рапорт!$P:$P,рапорт!$A:$A,A12)-SUMIFS(рапорт!$U:$U,рапорт!$A:$A,A12)/4 -> 12455 | L12: =L11+D12-SUMIFS(рапорт!$Q:$Q,рапорт!$A:$A,A12)-SUMIFS(рапорт!$U:$U,рапорт!$A:$A,A12)/4 -> 0 | M12: =M11+E12-SUMIFS(рапорт!$R:$R,рапорт!$A:$A,A12)-SUMIFS(рапорт!$U:$U,рапорт!$A:$A,A12)/4 -> 14417 | O12: 46031 | T12: =SUM(P12:S12) -> 0 | U12: =U11 -> 759900 | V12: =V11 -> 0 | W12: =W11 -> 0 | X12: =X11 -> 0 | Y12: =SUM(U12:X12) -> 759900
A13: 46032 | F13: =F12 -> 1729 | G13: =G12 -> 12455 | H13: =H12 -> 0 | I13: =I12 -> 14417 | J13: =J12+B13-SUMIFS(рапорт!$O:$O,рапорт!$A:$A,A13)-SUMIFS(рапорт!$U:$U,рапорт!$A:$A,A13)/4 -> 1729 | K13: =K12+C13-SUMIFS(рапорт!$P:$P,рапорт!$A:$A,A13)-SUMIFS(рапорт!$U:$U,рапорт!$A:$A,A13)/4 -> 12455 | L13: =L12+D13-SUMIFS(рапорт!$Q:$Q,рапорт!$A:$A,A13)-SUMIFS(рапорт!$U:$U,рапорт!$A:$A,A13)/4 -> 0 | M13: =M12+E13-SUMIFS(рапорт!$R:$R,рапорт!$A:$A,A13)-SUMIFS(рапорт!$U:$U,рапорт!$A:$A,A13)/4 -> 14417 | O13: 46032 | T13: =SUM(P13:S13) -> 0 | U13: =U12 -> 759900 | V13: =V12 -> 0 | W13: =W12 -> 0 | X13: =X12 -> 0 | Y13: =SUM(U13:X13) -> 759900
A14: 46033 | F14: =F13 -> 1729 | G14: =G13 -> 12455 | H14: =H13 -> 0 | I14: =I13 -> 14417 | J14: =J13+B14-SUMIFS(рапорт!$O:$O,рапорт!$A:$A,A14)-SUMIFS(рапорт!$U:$U,рапорт!$A:$A,A14)/4 -> 1729 | K14: =K13+C14-SUMIFS(рапорт!$P:$P,рапорт!$A:$A,A14)-SUMIFS(рапорт!$U:$U,рапорт!$A:$A,A14)/4 -> 12455 | L14: =L13+D14-SUMIFS(рапорт!$Q:$Q,рапорт!$A:$A,A14)-SUMIFS(рапорт!$U:$U,рапорт!$A:$A,A14)/4 -> 0 | M14: =M13+E14-SUMIFS(рапорт!$R:$R,рапорт!$A:$A,A14)-SUMIFS(рапорт!$U:$U,рапорт!$A:$A,A14)/4 -> 14417 | O14: 46033 | T14: =SUM(P14:S14) -> 0 | U14: =U13 -> 759900 | V14: =V13 -> 0 | W14: =W13 -> 0 | X14: =X13 -> 0 | Y14: =SUM(U14:X14) -> 759900
A15: 46034 | F15: =F14 -> 1729 | G15: =G14 -> 12455 | H15: =H14 -> 0 | I15: =I14 -> 14417 | J15: =J14+B15-SUMIFS(рапорт!$O:$O,рапорт!$A:$A,A15)-SUMIFS(рапорт!$U:$U,рапорт!$A:$A,A15)/4 -> 1729 | K15: =K14+C15-SUMIFS(рапорт!$P:$P,рапорт!$A:$A,A15)-SUMIFS(рапорт!$U:$U,рапорт!$A:$A,A15)/4 -> 12455 | L15: =L14+D15-SUMIFS(рапорт!$Q:$Q,рапорт!$A:$A,A15)-SUMIFS(рапорт!$U:$U,рапорт!$A:$A,A15)/4 -> 0 | M15: =M14+E15-SUMIFS(рапорт!$R:$R,рапорт!$A:$A,A15)-SUMIFS(рапорт!$U:$U,рапорт!$A:$A,A15)/4 -> 14417 | O15: 46034 | T15: =SUM(P15:S15) -> 0 | U15: =U14 -> 759900 | V15: =V14 -> 0 | W15: =W14 -> 0 | X15: =X14 -> 0 | Y15: =SUM(U15:X15) -> 759900
... A45: 46064 | F45: =F44 -> 1729 | G45: =G44 -> 12455 | H45: =H44 -> 0 | I45: =I44 -> 14417 | J45: =J44+B45-SUMIFS(рапорт!$O:$O,рапорт!$A:$A,A45)-SUMIFS(рапорт!$U:$U,рапорт!$A:$A,A45)/4 -> 1729 | K45: =K44+C45-SUMIFS(рапорт!$P:$P,рапорт!$A:$A,A45)-SUMIFS(рапорт!$U:$U,рапорт!$A:$A,A45)/4 -> 12455 | L45: =L44+D45-SUMIFS(рапорт!$Q:$Q,рапорт!$A:$A,A45)-SUMIFS(рапорт!$U:$U,рапорт!$A:$A,A45)/4 -> 0 | M45: =M44+E45-SUMIFS(рапорт!$R:$R,рапорт!$A:$A,A45)-SUMIFS(рапорт!$U:$U,рапорт!$A:$A,A45)/4 -> 14417 | O45: 46064 | T45: =SUM(P45:S45) -> 0 | U45: =U44 -> 759900 | V45: =V44 -> 0 | W45: =W44 -> 0 | X45: =X44 -> 0 | Y45: =SUM(U45:X45) -> 759900
